Workbook

Sheet 📊 DASHBOAD
A1: '''''''''''''''''''''''''''''''''''''''''''''''''''''''''''''''''''''''''''''''''''''''''
B2: Mês competência | C2: Ano competência | H2: 1. TOTAL | I2: =SUM(I4:I22) -> 4227.59 | J2: =SUM(J4:J22) -> 3620 | K2: =SUM(K4:K22) -> 4227.59 | L2: =SUM(L4:L22) -> 0.93433848
B3: Junho | C3: 2026 | H3: CATEGORIA | I3: VALOR PAGO | J3: VALOR A PAGAR | K3: TOTAL | L3: %
D4: Margem Cont: | E4: =(C7-C20)/C7 -> 0.88308667 | G4: CMV | H4: ='📈Det. Resultados'!B9 -> PROLABORE | I4: =SUMIFS('📋 Despesas'!$J$7:$J$17825,'📋 Despesas'!$F$7:$F$17825,H4,'📋 Despesas'!$C$7:$C$17825,$B$3,'📋 Despesas'!$D$7:$D$17825,$C$3) -> 2670 | J4: =SUMIFS('📋 Despesas'!$K$7:$K$17825,'📋 Despesas'!$F$7:$F$17825,H4,'📋 Despesas'!$C$7:$C$17825,$B$3,'📋 Despesas'!$D$7:$D$17825,$C$3) -> 2670 | K4: =I4 -> 2670 | L4: =IFERROR((K4/$K$2),0) -> 0.6315655
B5: (+) Fatur. Bruto | C5: =SUMIFS('💸 Receitas'!$I$5:$I$1127,'💸 Receitas'!$C$5:$C$1127,$C$3,'💸 Receitas'!$D$5:$D$1127,$B$3) -> 10500 | D5: MC1=Receita-DV -> MC=MC1/Receita | H5: ='📈Det. Resultados'!B10 -> INSS | I5: =SUMIFS('📋 Despesas'!$J$7:$J$17825,'📋 Despesas'!$F$7:$F$17825,H5,'📋 Despesas'!$C$7:$C$17825,$B$3,'📋 Despesas'!$D$7:$D$17825,$C$3) -> 330 | J5: =SUMIFS('📋 Despesas'!$K$7:$K$17825,'📋 Despesas'!$F$7:$F$17825,H5,'📋 Despesas'!$C$7:$C$17825,$B$3,'📋 Despesas'!$D$7:$D$17825,$C$3) -> 0 | K5: =I5 -> 330 | L5: =IFERROR((K5/$K$2),0) -> 0.078058658
B6: (-) Taxa | C6: =C7-C5 -> 0 | D6: Este % MC pagara os CFs =LL | H6: ='📈Det. Resultados'!B11 -> LUCRO | I6: =SUMIFS('📋 Despesas'!$J$7:$J$17825,'📋 Despesas'!$F$7:$F$17825,H6,'📋 Despesas'!$C$7:$C$17825,$B$3,'📋 Despesas'!$D$7:$D$17825,$C$3) -> 0 | J6: =SUMIFS('📋 Despesas'!$K$7:$K$17825,'📋 Despesas'!$F$7:$F$17825,H6,'📋 Despesas'!$C$7:$C$17825,$B$3,'📋 Despesas'!$D$7:$D$17825,$C$3) -> 0 | K6: =I6 -> 0 | L6: =IFERROR((K6/$K$2),0) -> 0
B7: (+) Fatur. Liquido | C7: =SUMIFS('💸 Receitas'!$J$7:$J$681,'💸 Receitas'!$C$7:$C$681,$C$3,'💸 Receitas'!$D$7:$D$681,$B$3) -> 10500 | D7: Após pgto dos CUSTOS FIXOS | H7: ='📈Det. Resultados'!B12 -> CONTABILIDADE | I7: =SUMIFS('📋 Despesas'!$J$7:$J$17825,'📋 Despesas'!$F$7:$F$17825,H7,'📋 Despesas'!$C$7:$C$17825,$B$3,'📋 Despesas'!$D$7:$D$17825,$C$3) -> 950 | J7: =SUMIFS('📋 Despesas'!$K$7:$K$17825,'📋 Despesas'!$F$7:$F$17825,H7,'📋 Despesas'!$C$7:$C$17825,$B$3,'📋 Despesas'!$D$7:$D$17825,$C$3) -> 950 | K7: =I7 -> 950 | L7: =IFERROR((K7/$K$2),0) -> 0.22471432
B8: (-) Despesas | C8: =-K2 -> -4227.59 | H8: ='📈Det. Resultados'!B13 -> OUTROS | I8: =SUMIFS('📋 Despesas'!$J$7:$J$17825,'📋 Despesas'!$F$7:$F$17825,H8,'📋 Despesas'!$C$7:$C$17825,$B$3,'📋 Despesas'!$D$7:$D$17825,$C$3) -> 0 | J8: =SUMIFS('📋 Despesas'!$K$7:$K$17825,'📋 Despesas'!$F$7:$F$17825,H8,'📋 Despesas'!$C$7:$C$17825,$B$3,'📋 Despesas'!$D$7:$D$17825,$C$3) -> 0 | K8: =I8 -> 0 | L8: =IFERROR((K8/$K$2),0) -> 0
B9: Lucro Liquido | C9: =C7+C8 -> 6272.41 | D9: =(C7*E4)-(C19+C21) -> 6272.41 | H9: ='📈Det. Resultados'!B14 -> ADM | I9: =SUMIFS('📋 Despesas'!$J$7:$J$17825,'📋 Despesas'!$F$7:$F$17825,H9,'📋 Despesas'!$C$7:$C$17825,$B$3,'📋 Despesas'!$D$7:$D$17825,$C$3) -> 277.59 | J9: =SUMIFS('📋 Despesas'!$K$7:$K$17825,'📋 Despesas'!$F$7:$F$17825,H9,'📋 Despesas'!$C$7:$C$17825,$B$3,'📋 Despesas'!$D$7:$D$17825,$C$3) -> 0 | K9: =I9 -> 277.59
B10: Margem liquida | C10: =IFERROR((C9/C5),0) -> 0.59737238 | D10: =(C19+C21)/E4 -> 3397.1751 | E10: P.Equilibrio | H10: ='📈Det. Resultados'!B15 -> 0 | I10: =SUMIFS('📋 Despesas'!$J$7:$J$17825,'📋 Despesas'!$F$7:$F$17825,H10,'📋 Despesas'!$C$7:$C$17825,$B$3,'📋 Despesas'!$D$7:$D$17825,$C$3) -> 0 | J10: =SUMIFS('📋 Despesas'!$K$7:$K$17825,'📋 Despesas'!$F$7:$F$17825,H10,'📋 Despesas'!$C$7:$C$17825,$B$3,'📋 Despesas'!$D$7:$D$17825,$C$3) -> 0 | K10: =I10 -> 0 | L10: =IFERROR((K10/$K$2),0) -> 0
H11: ='📈Det. Resultados'!B16 -> 0 | I11: =SUMIFS('📋 Despesas'!$J$7:$J$17825,'📋 Despesas'!$F$7:$F$17825,H11,'📋 Despesas'!$C$7:$C$17825,$B$3,'📋 Despesas'!$D$7:$D$17825,$C$3) -> 0 | J11: =SUMIFS('📋 Despesas'!$K$7:$K$17825,'📋 Despesas'!$F$7:$F$17825,H11,'📋 Despesas'!$C$7:$C$17825,$B$3,'📋 Despesas'!$D$7:$D$17825,$C$3) -> 0 | K11: =I11 -> 0 | L11: =IFERROR((K11/$K$2),0) -> 0
B12: CMV (até 35%) | C12: =IFERROR((#REF!/C5),0) -> 0 | D12: =SUM(K4:K9) -> 4227.59 | G12: DESP. ADMIN | H12: ='📈Det. Resultados'!B17 -> 0 | I12: =SUMIFS('📋 Despesas'!$J$7:$J$17825,'📋 Despesas'!$F$7:$F$17825,H12,'📋 Despesas'!$C$7:$C$17825,$B$3,'📋 Despesas'!$D$7:$D$17825,$C$3) -> 0 | J12: =SUMIFS('📋 Despesas'!$K$7:$K$17825,'📋 Despesas'!$F$7:$F$17825,H12,'📋 Despesas'!$C$7:$C$17825,$B$3,'📋 Despesas'!$D$7:$D$17825,$C$3) -> 0 | K12: =I12 -> 0 | L12: =IFERROR((K12/$K$2),0) -> 0
H13: ='📈Det. Resultados'!B18 -> 0 | I13: =SUMIFS('📋 Despesas'!$J$7:$J$17825,'📋 Despesas'!$F$7:$F$17825,H13,'📋 Despesas'!$C$7:$C$17825,$B$3,'📋 Despesas'!$D$7:$D$17825,$C$3) -> 0 | J13: =SUMIFS('📋 Despesas'!$K$7:$K$17825,'📋 Despesas'!$F$7:$F$17825,H13,'📋 Despesas'!$C$7:$C$17825,$B$3,'📋 Despesas'!$D$7:$D$17825,$C$3) -> 0 | K13: =I13 -> 0 | L13: =IFERROR((K13/$K$2),0) -> 0
B14: Desp. Adm (até 33%) | C14: =IFERROR(SUM(K11:K21)/C7,0) -> 0 | D14: =SUM(K11:K21) -> 0 | H14: ='📈Det. Resultados'!B19 -> 0 | I14: =SUMIFS('📋 Despesas'!$J$7:$J$17825,'📋 Despesas'!$F$7:$F$17825,H14,'📋 Despesas'!$C$7:$C$17825,$B$3,'📋 Despesas'!$D$7:$D$17825,$C$3) -> 0 | J14: =SUMIFS('📋 Despesas'!$K$7:$K$17825,'📋 Despesas'!$F$7:$F$17825,H14,'📋 Despesas'!$C$7:$C$17825,$B$3,'📋 Despesas'!$D$7:$D$17825,$C$3) -> 0 | K14: =I14 -> 0 | L14: =IFERROR((K14/$K$2),0) -> 0
H15: ='📈Det. Resultados'!B20 -> 0 | I15: =SUMIFS('📋 Despesas'!$J$7:$J$17825,'📋 Despesas'!$F$7:$F$17825,H15,'📋 Despesas'!$C$7:$C$17825,$B$3,'📋 Despesas'!$D$7:$D$17825,$C$3) -> 0 | J15: =SUMIFS('📋 Despesas'!$K$7:$K$17825,'📋 Despesas'!$F$7:$F$17825,H15,'📋 Despesas'!$C$7:$C$17825,$B$3,'📋 Despesas'!$D$7:$D$17825,$C$3) -> 0 | K15: =I15 -> 0 | L15: =IFERROR((K15/$K$2),0) -> 0
B16: EFICIÊNCIA EQUIPE | C16: =IFERROR((K12/C5),0) -> 0 | D16: =IFERROR((C5/(K12+K11)),) -> 0 | H16: ='📈Det. Resultados'!B21 -> 0 | I16: =SUMIFS('📋 Despesas'!$J$7:$J$17825,'📋 Despesas'!$F$7:$F$17825,H16,'📋 Despesas'!$C$7:$C$17825,$B$3,'📋 Despesas'!$D$7:$D$17825,$C$3) -> 0 | J16: =SUMIFS('📋 Despesas'!$K$7:$K$17825,'📋 Despesas'!$F$7:$F$17825,H16,'📋 Despesas'!$C$7:$C$17825,$B$3,'📋 Despesas'!$D$7:$D$17825,$C$3) -> 0 | K16: =I16 -> 0 | L16: =IFERROR((K16/$K$2),0) -> 0
B17: Peso Aluguel (até 10%) | C17: =IFERROR((D17/C5),0) -> 0 | D17: =K16 -> 0 | H17: ='📈Det. Resultados'!B22 -> DAS | I17: =SUMIFS('📋 Despesas'!$J$7:$J$17825,'📋 Despesas'!$F$7:$F$17825,H17,'📋 Despesas'!$C$7:$C$17825,$B$3,'📋 Despesas'!$D$7:$D$17825,$C$3) -> 0 | J17: =SUMIFS('📋 Despesas'!$K$7:$K$17825,'📋 Despesas'!$F$7:$F$17825,H17,'📋 Despesas'!$C$7:$C$17825,$B$3,'📋 Despesas'!$D$7:$D$17825,$C$3) -> 0 | K17: =I17 -> 0 | L17: =IFERROR((K17/$K$2),0) -> 0
H18: ='📈Det. Resultados'!B23 -> TAXAS | I18: =SUMIFS('📋 Despesas'!$J$7:$J$17825,'📋 Despesas'!$F$7:$F$17825,H18,'📋 Despesas'!$C$7:$C$17825,$B$3,'📋 Despesas'!$D$7:$D$17825,$C$3) -> 0 | J18: =SUMIFS('📋 Despesas'!$K$7:$K$17825,'📋 Despesas'!$F$7:$F$17825,H18,'📋 Despesas'!$C$7:$C$17825,$B$3,'📋 Despesas'!$D$7:$D$17825,$C$3) -> 0 | K18: =I18 -> 0 | L18: =IFERROR((K18/$K$2),0) -> 0
B19: FIXO | C19: =SUMIFS('📋 Despesas'!$J$7:$J$18166,'📋 Despesas'!$H$7:$H$18166,B19,'📋 Despesas'!$C$7:$C$18166,$B$3,'📋 Despesas'!$D$7:$D$18166,$C$3) -> 2670 | D19: =C19/$C$22 -> 0.6315655 | H19: ='📈Det. Resultados'!B24 -> 0 | I19: =SUMIFS('📋 Despesas'!$J$7:$J$17825,'📋 Despesas'!$F$7:$F$17825,H19,'📋 Despesas'!$C$7:$C$17825,$B$3,'📋 Despesas'!$D$7:$D$17825,$C$3) -> 0 | J19: =SUMIFS('📋 Despesas'!$K$7:$K$17825,'📋 Despesas'!$F$7:$F$17825,H19,'📋 Despesas'!$C$7:$C$17825,$B$3,'📋 Despesas'!$D$7:$D$17825,$C$3) -> 0 | K19: =I19 -> 0 | L19: =IFERROR((K19/$K$2),0) -> 0
B20: VARIÁVEL | C20: =SUMIFS('📋 Despesas'!$J$7:$J$18166,'📋 Despesas'!$H$7:$H$18166,B20,'📋 Despesas'!$C$7:$C$18166,$B$3,'📋 Despesas'!$D$7:$D$18166,$C$3) -> 1227.59 | D20: =C20/$C$22 -> 0.29037584 | H20: ='📈Det. Resultados'!B25 -> 0 | I20: =SUMIFS('📋 Despesas'!$J$7:$J$17825,'📋 Despesas'!$F$7:$F$17825,H20,'📋 Despesas'!$C$7:$C$17825,$B$3,'📋 Despesas'!$D$7:$D$17825,$C$3) -> 0 | J20: =SUMIFS('📋 Despesas'!$K$7:$K$17825,'📋 Despesas'!$F$7:$F$17825,H20,'📋 Despesas'!$C$7:$C$17825,$B$3,'📋 Despesas'!$D$7:$D$17825,$C$3) -> 0 | K20: =I20 -> 0 | L20: =IFERROR((K20/$K$2),0) -> 0
B21: FIXO/VARIÁVEL | C21: =SUMIFS('📋 Despesas'!$J$7:$J$18166,'📋 Despesas'!$H$7:$H$18166,B21,'📋 Despesas'!$C$7:$C$18166,$B$3,'📋 Despesas'!$D$7:$D$18166,$C$3) -> 330 | D21: =C21/$C$22 -> 0.078058658 | H21: ='📈Det. Resultados'!B26 -> 0 | I21: =SUMIFS('📋 Despesas'!$J$7:$J$17825,'📋 Despesas'!$F$7:$F$17825,H21,'📋 Despesas'!$C$7:$C$17825,$B$3,'📋 Despesas'!$D$7:$D$17825,$C$3) -> 0 | J21: =SUMIFS('📋 Despesas'!$K$7:$K$17825,'📋 Despesas'!$F$7:$F$17825,H21,'📋 Despesas'!$C$7:$C$17825,$B$3,'📋 Despesas'!$D$7:$D$17825,$C$3) -> 0 | K21: =I21 -> 0 | L21: =IFERROR((K21/$K$2),0) -> 0
B22: TOTAL | C22: =SUM(C19:C21) -> 4227.59 | D22: =SUM(D19:D21) -> 1 | H22: ='📈Det. Resultados'!B27 -> 0 | I22: =SUMIFS('📋 Despesas'!$J$7:$J$17825,'📋 Despesas'!$F$7:$F$17825,H22,'📋 Despesas'!$C$7:$C$17825,$B$3,'📋 Despesas'!$D$7:$D$17825,$C$3) -> 0 | J22: =SUMIFS('📋 Despesas'!$K$7:$K$17825,'📋 Despesas'!$F$7:$F$17825,H22,'📋 Despesas'!$C$7:$C$17825,$B$3,'📋 Despesas'!$D$7:$D$17825,$C$3) -> 0 | K22: =I22 -> 0 | L22: =IFERROR((K22/$K$2),0) -> 0
B23: FIXO + FIXO VARIÁVEL: | C23: =C19+C21 -> 3000 | D23: =C23/C7 -> 0.28571429
F26: 1

Sheet 📋 Despesas
L2: Conferência | N2: PESQUISA SALDO A PAGAR
E3: CONTAS A PAGAR | G3: =YEAR((TODAY()-31)) -> 2026 | H3: =TEXT(DATE(YEAR(TODAY()),MONTH(TODAY())-1,1),"mmmm") -> maio | I3: MÊS PASSADO | J3: =SUMIFS($J:$J,$O:$O,$H$3) -> 1637.92 | K3: =SUMIFS(K:K,O:O,H3) -> 1637.92 | L3: =IF(M3=(SUMIFS('📈Det. Resultados'!$7:$7,'📈Det. Resultados'!$3:$3,H3,'📈Det. Resultados'!$2:$2,G3)),"OK","ERRO") -> ERRO | M3: =SUMIFS(M:M,O:O,H3) -> 1637.92 | N3: DATA INICIAL | O3: 46174 | P3: =SUMIFS(K7:K8183,'📋 Despesas'!N7:N8183,">="&O3,'📋 Despesas'!N7:N8183,"<="&O4) -> 3620
E4: ='💰Fluxo de Pagamentos'!B3 -> HOJE | F4: ='💰Fluxo de Pagamentos'!C3 -> 0 | G4: =YEAR((TODAY())) -> 2026 | H4: =TEXT(TODAY(),"mmmm") -> junho | I4: MÊS ATUAL | J4: =SUMIFS($J7:$J17825,$O7:$O17825,$H4) -> 4430.03 | K4: =SUMIFS(K:K,O:O,H4) -> 3620 | L4: =IF(M4=(SUMIFS('📈Det. Resultados'!$7:$7,'📈Det. Resultados'!$3:$3,H4)),"OK","ERRO") -> ERRO | M4: =SUMIFS(M:M,O:O,H4) -> 4430.03 | N4: DATA FINAL | O4: 46203
I5: TOTAL | J5: =J4 -> 4430.03 | K5: =SUM(K7:K17825) -> 9947.92 | M5: =SUBTOTAL(9,J7:J17825) -> 10757.95
B6: Data | C6: Mês | D6: Ano | E6: Item | F6: Grupo | G6: ENTIDADE | H6: C. CUSTO | I6: Valor Unitario | J6: TOTAL | K6: Valor a Pagar | L6: Forma de pgto | M6: Total | N6: Data a pagar | O6: Mês Pgto | P6: Ano Pgto | Q6: Status Pgto | R6: AUDITORIA
B7: 46143 | C7: =IF(B7<>"",PROPER(TEXT(B7,"mmmm")),"") -> Maio | D7: =IF(B7<>"",TEXT(B7,"aaaa"),"") -> 2026 | E7: INSS | F7: INSS | G7: RECEITA FEDERAL | H7: FIXO/VARIÁVEL | I7: 187 | J7: 202.44 | K7: 0 | L7: PIX | M7: =J7 -> 202.44 | N7: 46184 | O7: =IF(N7<>"",TEXT(N7,"mmmm"),"") -> junho | P7: =IF(N7<>"",TEXT(N7,"aaaa"),"") -> 2026 | Q7: =IF(J7=0,"",IF(K7=0,"PAGO","A PAGAR")) -> PAGO | R7: =IF(Q7="PAGO", "✓ OK", IF(Q7="A PAGAR", IF(N7<TODAY(), "⚠ EM ATRASO", "EM DIA"), "")) -> ✓ OK
B8: 46143 | C8: =IF(B8<>"",PROPER(TEXT(B8,"mmmm")),"") -> Maio | D8: =IF(B8<>"",TEXT(B8,"aaaa"),"") -> 2026 | E8: PROLABORE | F8: PROLABORE | G8: NVS | H8: FIXO | I8: 1637.92 | J8: =I8 -> 1637.92 | K8: =J8 -> 1637.92 | L8: PIX | M8: =J8 -> 1637.92 | N8: 46147 | O8: =IF(N8<>"",TEXT(N8,"mmmm"),"") -> maio | P8: =IF(N8<>"",TEXT(N8,"aaaa"),"") -> 2026 | Q8: =IF(J8=0,"",IF(K8=0,"PAGO","A PAGAR")) -> A PAGAR | R8: =IF(Q8="PAGO", "✓ OK", IF(Q8="A PAGAR", IF(N8<TODAY(), "⚠ EM ATRASO", "EM DIA"), "")) -> ⚠ EM ATRASO
B9: 46174 | C9: =IF(B9<>"",PROPER(TEXT(B9,"mmmm")),"") -> Junho | D9: =IF(B9<>"",TEXT(B9,"aaaa"),"") -> 2026 | E9: INSS | F9: INSS | G9: RECEITA FEDERAL | H9: FIXO/VARIÁVEL | I9: 330 | J9: =I9 -> 330 | K9: 0 | L9: PIX | M9: =J9 -> 330 | N9: 46192 | O9: =IF(N9<>"",TEXT(N9,"mmmm"),"") -> junho | P9: =IF(N9<>"",TEXT(N9,"aaaa"),"") -> 2026 | Q9: =IF(J9=0,"",IF(K9=0,"PAGO","A PAGAR")) -> PAGO | R9: =IF(Q9="PAGO", "✓ OK", IF(Q9="A PAGAR", IF(N9<TODAY(), "⚠ EM ATRASO", "EM DIA"), "")) -> ✓ OK
B10: 46174 | C10: =IF(B10<>"",PROPER(TEXT(B10,"mmmm")),"") -> Junho | D10: =IF(B10<>"",TEXT(B10,"aaaa"),"") -> 2026 | E10: PROLABORE | F10: PROLABORE | G10: NVS | H10: FIXO | I10: =3000-330 -> 2670 | J10: =I10 -> 2670 | K10: =J10 -> 2670 | L10: PIX | M10: =J10 -> 2670 | N10: 46178 | O10: =IF(N10<>"",TEXT(N10,"mmmm"),"") -> junho | P10: =IF(N10<>"",TEXT(N10,"aaaa"),"") -> 2026 | Q10: =IF(J10=0,"",IF(K10=0,"PAGO","A PAGAR")) -> A PAGAR | R10: =IF(Q10="PAGO", "✓ OK", IF(Q10="A PAGAR", IF(N10<TODAY(), "⚠ EM ATRASO", "EM DIA"), "")) -> ⚠ EM ATRASO
B11: 46204 | C11: =IF(B11<>"",PROPER(TEXT(B11,"mmmm")),"") -> Julho | D11: =IF(B11<>"",TEXT(B11,"aaaa"),"") -> 2026 | E11: CONTABILIDADE | F11: CONTABILIDADE | G11: ESCRITURAL | H11: FIXO | I11: 590 | J11: =I11 -> 590 | K11: =J11 -> 590 | L11: PIX | M11: =J11 -> 590 | N11: 46213 | O11: =IF(N11<>"",TEXT(N11,"mmmm"),"") -> julho | P11: =IF(N11<>"",TEXT(N11,"aaaa"),"") -> 2026 | Q11: =IF(J11=0,"",IF(K11=0,"PAGO","A PAGAR")) -> A PAGAR | R11: =IF(Q11="PAGO", "✓ OK", IF(Q11="A PAGAR", IF(N11<TODAY(), "⚠ EM ATRASO", "EM DIA"), "")) -> EM DIA
B12: 46181 | C12: =IF(B12<>"",PROPER(TEXT(B12,"mmmm")),"") -> Junho | D12: =IF(B12<>"",TEXT(B12,"aaaa"),"") -> 2026 | E12: ABERTURA DA EMPRESA | F12: CONTABILIDADE | G12: ESCRITURAL | H12: VARIÁVEL | I12: 950 | J12: =I12 -> 950 | K12: =J12 -> 950 | L12: BOLETO | M12: =J12 -> 950 | N12: 46203 | O12: =IF(N12<>"",TEXT(N12,"mmmm"),"") -> junho | P12: =IF(N12<>"",TEXT(N12,"aaaa"),"") -> 2026 | Q12: =IF(J12=0,"",IF(K12=0,"PAGO","A PAGAR")) -> A PAGAR | R12: =IF(Q12="PAGO", "✓ OK", IF(Q12="A PAGAR", IF(N12<TODAY(), "⚠ EM ATRASO", "EM DIA"), "")) -> EM DIA
B13: 46187 | C13: =IF(B13<>"",PROPER(TEXT(B13,"mmmm")),"") -> Junho | D13: =IF(B13<>"",TEXT(B13,"aaaa"),"") -> 2026 | E13: ALMOÇO CLIENTE | F13: ADM | G13: QUINTILHA | H13: VARIÁVEL | I13: 106 | J13: =I13 -> 106 | K13: 0 | L13: PIX | M13: =J13 -> 106 | N13: 46187 | O13: =IF(N13<>"",TEXT(N13,"mmmm"),"") -> junho | P13: =IF(N13<>"",TEXT(N13,"aaaa"),"") -> 2026 | Q13: =IF(J13=0,"",IF(K13=0,"PAGO","A PAGAR")) -> PAGO | R13: =IF(Q13="PAGO", "✓ OK", IF(Q13="A PAGAR", IF(N13<TODAY(), "⚠ EM ATRASO", "EM DIA"), "")) -> ✓ OK
B14: 46187 | C14: =IF(B14<>"",PROPER(TEXT(B14,"mmmm")),"") -> Junho | D14: =IF(B14<>"",TEXT(B14,"aaaa"),"") -> 2026 | E14: ABASTECIMENTO | F14: ADM | G14: POSTO 44 | H14: VARIÁVEL | I14: 171.59 | J14: =I14 -> 171.59 | K14: 0 | L14: PIX | M14: =J14 -> 171.59 | N14: 46187 | O14: =IF(N14<>"",TEXT(N14,"mmmm"),"") -> junho | P14: =IF(N14<>"",TEXT(N14,"aaaa"),"") -> 2026 | Q14: =IF(J14=0,"",IF(K14=0,"PAGO","A PAGAR")) -> PAGO | R14: =IF(Q14="PAGO", "✓ OK", IF(Q14="A PAGAR", IF(N14<TODAY(), "⚠ EM ATRASO", "EM DIA"), "")) -> ✓ OK
B15: 46204 | C15: =IF(B15<>"",PROPER(TEXT(B15,"mmmm")),"") -> Julho | D15: =IF(B15<>"",TEXT(B15,"aaaa"),"") -> 2026 | E15: PROLABORE | F15: PROLABORE | G15: NVS | H15: FIXO | I15: =3500-I16 -> 3115 | J15: =I15 -> 3115 | K15: =J15 -> 3115 | L15: PIX | M15: =J15 -> 3115 | N15: 46208 | O15: =IF(N15<>"",TEXT(N15,"mmmm"),"") -> julho | P15: =IF(N15<>"",TEXT(N15,"aaaa"),"") -> 2026 | Q15: =IF(J15=0,"",IF(K15=0,"PAGO","A PAGAR")) -> A PAGAR | R15: =IF(Q15="PAGO", "✓ OK", IF(Q15="A PAGAR", IF(N15<TODAY(), "⚠ EM ATRASO", "EM DIA"), "")) -> EM DIA
B16: 46204 | C16: =IF(B16<>"",PROPER(TEXT(B16,"mmmm")),"") -> Julho | D16: =IF(B16<>"",TEXT(B16,"aaaa"),"") -> 2026 | E16: INSS | F16: INSS | G16: RECEITA FEDERAL | H16: FIXO | I16: 385 | J16: =I16 -> 385 | K16: =J16 -> 385 | L16: PIX | M16: =J16 -> 385 | N16: 46223 | O16: =IF(N16<>"",TEXT(N16,"mmmm"),"") -> julho | P16: =IF(N16<>"",TEXT(N16,"aaaa"),"") -> 2026 | Q16: =IF(J16=0,"",IF(K16=0,"PAGO","A PAGAR")) -> A PAGAR | R16: =IF(Q16="PAGO", "✓ OK", IF(Q16="A PAGAR", IF(N16<TODAY(), "⚠ EM ATRASO", "EM DIA"), "")) -> EM DIA
B17: 46204 | C17: =IF(B17<>"",PROPER(TEXT(B17,"mmmm")),"") -> Julho | D17: =IF(B17<>"",TEXT(B17,"aaaa"),"") -> 2026 | E17: DAS | F17: DAS | G17: RECEITA FEDERAL | H17: FIXO | I17: 600 | J17: =I17 -> 600 | K17: =J17 -> 600 | L17: PIX | M17: =J17 -> 600 | N17: 46223 | O17: =IF(N17<>"",TEXT(N17,"mmmm"),"") -> julho | P17: =IF(N17<>"",TEXT(N17,"aaaa"),"") -> 2026 | Q17: =IF(J17=0,"",IF(K17=0,"PAGO","A PAGAR")) -> A PAGAR | R17: =IF(Q17="PAGO", "✓ OK", IF(Q17="A PAGAR", IF(N17<TODAY(), "⚠ EM ATRASO", "EM DIA"), "")) -> EM DIA
C18: =IF(B18<>"",PROPER(TEXT(B18,"mmmm")),"") | D18: =IF(B18<>"",TEXT(B18,"aaaa"),"") | J18: =I18 -> 0 | K18: =J18 -> 0 | M18: =J18 -> 0 | O18: =IF(N18<>"",TEXT(N18,"mmmm"),"") | P18: =IF(N18<>"",TEXT(N18,"aaaa"),"") | Q18: =IF(J18=0,"",IF(K18=0,"PAGO","A PAGAR")) | R18: =IF(Q18="PAGO", "✓ OK", IF(Q18="A PAGAR", IF(N18<TODAY(), "⚠ EM ATRASO", "EM DIA"), ""))
C19: =IF(B19<>"",PROPER(TEXT(B19,"mmmm")),"") | D19: =IF(B19<>"",TEXT(B19,"aaaa"),"") | J19: =I19 -> 0 | K19: =J19 -> 0 | M19: =J19 -> 0 | O19: =IF(N19<>"",TEXT(N19,"mmmm"),"") | P19: =IF(N19<>"",TEXT(N19,"aaaa"),"") | Q19: =IF(J19=0,"",IF(K19=0,"PAGO","A PAGAR")) | R19: =IF(Q19="PAGO", "✓ OK", IF(Q19="A PAGAR", IF(N19<TODAY(), "⚠ EM ATRASO", "EM DIA"), ""))
C20: =IF(B20<>"",PROPER(TEXT(B20,"mmmm")),"") | D20: =IF(B20<>"",TEXT(B20,"aaaa"),"") | J20: =I20 -> 0 | K20: =J20 -> 0 | M20: =J20 -> 0 | O20: =IF(N20<>"",TEXT(N20,"mmmm"),"") | P20: =IF(N20<>"",TEXT(N20,"aaaa"),"") | Q20: =IF(J20=0,"",IF(K20=0,"PAGO","A PAGAR")) | R20: =IF(Q20="PAGO", "✓ OK", IF(Q20="A PAGAR", IF(N20<TODAY(), "⚠ EM ATRASO", "EM DIA"), ""))
C21: =IF(B21<>"",PROPER(TEXT(B21,"mmmm")),"") | D21: =IF(B21<>"",TEXT(B21,"aaaa"),"") | J21: =I21 -> 0 | K21: =J21 -> 0 | M21: =J21 -> 0 | O21: =IF(N21<>"",TEXT(N21,"mmmm"),"") | P21: =IF(N21<>"",TEXT(N21,"aaaa"),"") | Q21: =IF(J21=0,"",IF(K21=0,"PAGO","A PAGAR")) | R21: =IF(Q21="PAGO", "✓ OK", IF(Q21="A PAGAR", IF(N21<TODAY(), "⚠ EM ATRASO", "EM DIA"), ""))
C22: =IF(B22<>"",PROPER(TEXT(B22,"mmmm")),"") | D22: =IF(B22<>"",TEXT(B22,"aaaa"),"") | J22: =I22 -> 0 | K22: =J22 -> 0 | M22: =J22 -> 0 | O22: =IF(N22<>"",TEXT(N22,"mmmm"),"") | P22: =IF(N22<>"",TEXT(N22,"aaaa"),"") | Q22: =IF(J22=0,"",IF(K22=0,"PAGO","A PAGAR")) | R22: =IF(Q22="PAGO", "✓ OK", IF(Q22="A PAGAR", IF(N22<TODAY(), "⚠ EM ATRASO", "EM DIA"), ""))
C23: =IF(B23<>"",PROPER(TEXT(B23,"mmmm")),"") | D23: =IF(B23<>"",TEXT(B23,"aaaa"),"") | J23: =I23 -> 0 | K23: =J23 -> 0 | M23: =J23 -> 0 | O23: =IF(N23<>"",TEXT(N23,"mmmm"),"") | P23: =IF(N23<>"",TEXT(N23,"aaaa"),"") | Q23: =IF(J23=0,"",IF(K23=0,"PAGO","A PAGAR")) | R23: =IF(Q23="PAGO", "✓ OK", IF(Q23="A PAGAR", IF(N23<TODAY(), "⚠ EM ATRASO", "EM DIA"), ""))
C24: =IF(B24<>"",PROPER(TEXT(B24,"mmmm")),"") | D24: =IF(B24<>"",TEXT(B24,"aaaa"),"") | J24: =I24 -> 0 | K24: =J24 -> 0 | M24: =J24 -> 0 | O24: =IF(N24<>"",TEXT(N24,"mmmm"),"") | P24: =IF(N24<>"",TEXT(N24,"aaaa"),"") | Q24: =IF(J24=0,"",IF(K24=0,"PAGO","A PAGAR")) | R24: =IF(Q24="PAGO", "✓ OK", IF(Q24="A PAGAR", IF(N24<TODAY(), "⚠ EM ATRASO", "EM DIA"), ""))
C25: =IF(B25<>"",PROPER(TEXT(B25,"mmmm")),"") | D25: =IF(B25<>"",TEXT(B25,"aaaa"),"") | J25: =I25 -> 0 | K25: =J25 -> 0 | M25: =J25 -> 0 | O25: =IF(N25<>"",TEXT(N25,"mmmm"),"") | P25: =IF(N25<>"",TEXT(N25,"aaaa"),"") | Q25: =IF(J25=0,"",IF(K25=0,"PAGO","A PAGAR")) | R25: =IF(Q25="PAGO", "✓ OK", IF(Q25="A PAGAR", IF(N25<TODAY(), "⚠ EM ATRASO", "EM DIA"), ""))
C26: =IF(B26<>"",PROPER(TEXT(B26,"mmmm")),"") | D26: =IF(B26<>"",TEXT(B26,"aaaa"),"") | J26: =I26 -> 0 | K26: =J26 -> 0 | M26: =J26 -> 0 | O26: =IF(N26<>"",TEXT(N26,"mmmm"),"") | P26: =IF(N26<>"",TEXT(N26,"aaaa"),"") | Q26: =IF(J26=0,"",IF(K26=0,"PAGO","A PAGAR")) | R26: =IF(Q26="PAGO", "✓ OK", IF(Q26="A PAGAR", IF(N26<TODAY(), "⚠ EM ATRASO", "EM DIA"), ""))
C27: =IF(B27<>"",PROPER(TEXT(B27,"mmmm")),"") | D27: =IF(B27<>"",TEXT(B27,"aaaa"),"") | J27: =I27 -> 0 | K27: =J27 -> 0 | M27: =J27 -> 0 | O27: =IF(N27<>"",TEXT(N27,"mmmm"),"") | P27: =IF(N27<>"",TEXT(N27,"aaaa"),"") | Q27: =IF(J27=0,"",IF(K27=0,"PAGO","A PAGAR")) | R27: =IF(Q27="PAGO", "✓ OK", IF(Q27="A PAGAR", IF(N27<TODAY(), "⚠ EM ATRASO", "EM DIA"), ""))
C28: =IF(B28<>"",PROPER(TEXT(B28,"mmmm")),"") | D28: =IF(B28<>"",TEXT(B28,"aaaa"),"") | J28: =I28 -> 0 | K28: =J28 -> 0 | M28: =J28 -> 0 | O28: =IF(N28<>"",TEXT(N28,"mmmm"),"") | P28: =IF(N28<>"",TEXT(N28,"aaaa"),"") | Q28: =IF(J28=0,"",IF(K28=0,"PAGO","A PAGAR")) | R28: =IF(Q28="PAGO", "✓ OK", IF(Q28="A PAGAR", IF(N28<TODAY(), "⚠ EM ATRASO", "EM DIA"), ""))
C29: =IF(B29<>"",PROPER(TEXT(B29,"mmmm")),"") | D29: =IF(B29<>"",TEXT(B29,"aaaa"),"") | J29: =I29 -> 0 | K29: =J29 -> 0 | M29: =J29 -> 0 | O29: =IF(N29<>"",TEXT(N29,"mmmm"),"") | P29: =IF(N29<>"",TEXT(N29,"aaaa"),"") | Q29: =IF(J29=0,"",IF(K29=0,"PAGO","A PAGAR")) | R29: =IF(Q29="PAGO", "✓ OK", IF(Q29="A PAGAR", IF(N29<TODAY(), "⚠ EM ATRASO", "EM DIA"), ""))
... C125: =IF(B125<>"",PROPER(TEXT(B125,"mmmm")),"") | D125: =IF(B125<>"",TEXT(B125,"aaaa"),"") | J125: =I125 -> 0 | K125: =J125 -> 0 | M125: =J125 -> 0 | O125: =IF(N125<>"",TEXT(N125,"mmmm"),"") | P125: =IF(N125<>"",TEXT(N125,"aaaa"),"") | Q125: =IF(J125=0,"",IF(K125=0,"PAGO","A PAGAR")) | R125: =IF(Q125="PAGO", "✓ OK", IF(Q125="A PAGAR", IF(N125<TODAY(), "⚠ EM ATRASO", "EM DIA"), ""))
C126: =IF(B126<>"",PROPER(TEXT(B126,"mmmm")),"") | D126: =IF(B126<>"",TEXT(B126,"aaaa"),"") | K126: =J126 -> 0 | M126: =J126 -> 0 | O126: =IF(N126<>"",TEXT(N126,"mmmm"),"") | P126: =IF(N126<>"",TEXT(N126,"aaaa"),"") | Q126: =IF(J126=0,"",IF(K126=0,"PAGO","A PAGAR")) | R126: =IF(Q126="PAGO", "✓ OK", IF(Q126="A PAGAR", IF(N126<TODAY(), "⚠ EM ATRASO", "EM DIA"), ""))
C127: =IF(B127<>"",PROPER(TEXT(B127,"mmmm")),"") | D127: =IF(B127<>"",TEXT(B127,"aaaa"),"") | K127: =J127 -> 0 | M127: =J127 -> 0 | O127: =IF(N127<>"",TEXT(N127,"mmmm"),"") | P127: =IF(N127<>"",TEXT(N127,"aaaa"),"") | Q127: =IF(J127=0,"",IF(K127=0,"PAGO","A PAGAR")) | R127: =IF(Q127="PAGO", "✓ OK", IF(Q127="A PAGAR", IF(N127<TODAY(), "⚠ EM ATRASO", "EM DIA"), ""))
C128: =IF(B128<>"",PROPER(TEXT(B128,"mmmm")),"") | D128: =IF(B128<>"",TEXT(B128,"aaaa"),"") | K128: =J128 -> 0 | M128: =J128 -> 0 | O128: =IF(N128<>"",TEXT(N128,"mmmm"),"") | P128: =IF(N128<>"",TEXT(N128,"aaaa"),"") | Q128: =IF(J128=0,"",IF(K128=0,"PAGO","A PAGAR")) | R128: =IF(Q128="PAGO", "✓ OK", IF(Q128="A PAGAR", IF(N128<TODAY(), "⚠ EM ATRASO", "EM DIA"), ""))
C129: =IF(B129<>"",PROPER(TEXT(B129,"mmmm")),"") | D129: =IF(B129<>"",TEXT(B129,"aaaa"),"") | K129: =J129 -> 0 | M129: =J129 -> 0 | O129: =IF(N129<>"",TEXT(N129,"mmmm"),"") | P129: =IF(N129<>"",TEXT(N129,"aaaa"),"") | Q129: =IF(J129=0,"",IF(K129=0,"PAGO","A PAGAR")) | R129: =IF(Q129="PAGO", "✓ OK", IF(Q129="A PAGAR", IF(N129<TODAY(), "⚠ EM ATRASO", "EM DIA"), ""))
C130: =IF(B130<>"",PROPER(TEXT(B130,"mmmm")),"") | D130: =IF(B130<>"",TEXT(B130,"aaaa"),"") | K130: =J130 -> 0 | M130: =J130 -> 0 | P130: =IF(N130<>"",TEXT(N130,"aaaa"),"") | Q130: =IF(J130=0,"",IF(K130=0,"PAGO","A PAGAR")) | R130: =IF(Q130="PAGO", "✓ OK", IF(Q130="A PAGAR", IF(N130<TODAY(), "⚠ EM ATRASO", "EM DIA"), ""))
C131: =IF(B131<>"",PROPER(TEXT(B131,"mmmm")),"") | D131: =IF(B131<>"",TEXT(B131,"aaaa"),"") | K131: =J131 -> 0 | M131: =J131 -> 0 | P131: =IF(N131<>"",TEXT(N131,"aaaa"),"") | Q131: =IF(J131=0,"",IF(K131=0,"PAGO","A PAGAR")) | R131: =IF(Q131="PAGO", "✓ OK", IF(Q131="A PAGAR", IF(N131<TODAY(), "⚠ EM ATRASO", "EM DIA"), ""))
C132: =IF(B132<>"",PROPER(TEXT(B132,"mmmm")),"") | D132: =IF(B132<>"",TEXT(B132,"aaaa"),"") | K132: =J132 -> 0 | M132: =J132 -> 0 | P132: =IF(N132<>"",TEXT(N132,"aaaa"),"") | Q132: =IF(J132=0,"",IF(K132=0,"PAGO","A PAGAR")) | R132: =IF(Q132="PAGO", "✓ OK", IF(Q132="A PAGAR", IF(N132<TODAY(), "⚠ EM ATRASO", "EM DIA"), ""))
C133: =IF(B133<>"",PROPER(TEXT(B133,"mmmm")),"") | D133: =IF(B133<>"",TEXT(B133,"aaaa"),"") | K133: =J133 -> 0 | M133: =J133 -> 0 | R133: =IF(Q133="PAGO", "✓ OK", IF(Q133="A PAGAR", IF(N133<TODAY(), "⚠ EM ATRASO", "EM DIA"), ""))

Sheet 💸  Receitas
H5: 0.06
A6: Data | B6: Dia / semana | C6: ANO | D6: MES | E6: DESCRIÇÃO | F6: NOTA FISCAL | G6: Receita | H6: Imposto | I6: Total Bruto | J6: Total Liquido
A7: 46174 | B7: =IF(A7="","",TEXT(A7,"DDDD")) -> segunda-feira | C7: =IF(A7<>"",TEXT(A7,"aaaa"),"") -> 2026 | D7: =IF(A7<>"",PROPER(TEXT(A7,"Mmmm")),"") -> Junho | E7: FATURAMENTO | F7: 1 | G7: 10000 | H7: 0 | I7: =G7 -> 10000 | J7: =IF(I7=0,"",I7-H7) -> 10000
A8: 46175 | B8: =IF(A8="","",TEXT(A8,"DDDD")) -> terça-feira | C8: =IF(A8<>"",TEXT(A8,"aaaa"),"") -> 2026 | D8: =IF(A8<>"",PROPER(TEXT(A8,"Mmmm")),"") -> Junho | E8: ABERTURA DE CONTA | G8: 500 | H8: 0 | I8: =G8 -> 500 | J8: =IF(I8=0,"",I8-H8) -> 500
B9: =IF(A9="","",TEXT(A9,"DDDD")) | C9: =IF(A9<>"",TEXT(A9,"aaaa"),"") | D9: =IF(A9<>"",PROPER(TEXT(A9,"Mmmm")),"") | H9: =IF(G9=0,"",G9*$H$5) | I9: =G9 -> 0 | J9: =IF(I9=0,"",I9-H9)
B10: =IF(A10="","",TEXT(A10,"DDDD")) | C10: =IF(A10<>"",TEXT(A10,"aaaa"),"") | D10: =IF(A10<>"",PROPER(TEXT(A10,"Mmmm")),"") | H10: =IF(G10=0,"",G10*$H$5) | I10: =G10 -> 0 | J10: =IF(I10=0,"",I10-H10)
B11: =IF(A11="","",TEXT(A11,"DDDD")) | C11: =IF(A11<>"",TEXT(A11,"aaaa"),"") | D11: =IF(A11<>"",PROPER(TEXT(A11,"Mmmm")),"") | H11: =IF(G11=0,"",G11*$H$5) | I11: =G11 -> 0 | J11: =IF(I11=0,"",I11-H11)
B12: =IF(A12="","",TEXT(A12,"DDDD")) | C12: =IF(A12<>"",TEXT(A12,"aaaa"),"") | D12: =IF(A12<>"",PROPER(TEXT(A12,"Mmmm")),"") | H12: =IF(G12=0,"",G12*$H$5) | I12: =G12 -> 0 | J12: =IF(I12=0,"",I12-H12)
B13: =IF(A13="","",TEXT(A13,"DDDD")) | C13: =IF(A13<>"",TEXT(A13,"aaaa"),"") | D13: =IF(A13<>"",PROPER(TEXT(A13,"Mmmm")),"") | H13: =IF(G13=0,"",G13*$H$5) | I13: =G13 -> 0 | J13: =IF(I13=0,"",I13-H13)
B14: =IF(A14="","",TEXT(A14,"DDDD")) | C14: =IF(A14<>"",TEXT(A14,"aaaa"),"") | D14: =IF(A14<>"",PROPER(TEXT(A14,"Mmmm")),"") | H14: =IF(G14=0,"",G14*$H$5) | I14: =G14 -> 0 | J14: =IF(I14=0,"",I14-H14)
B15: =IF(A15="","",TEXT(A15,"DDDD")) | C15: =IF(A15<>"",TEXT(A15,"aaaa"),"") | D15: =IF(A15<>"",PROPER(TEXT(A15,"Mmmm")),"") | H15: =IF(G15=0,"",G15*$H$5) | I15: =G15 -> 0 | J15: =IF(I15=0,"",I15-H15)
B16: =IF(A16="","",TEXT(A16,"DDDD")) | C16: =IF(A16<>"",TEXT(A16,"aaaa"),"") | D16: =IF(A16<>"",PROPER(TEXT(A16,"Mmmm")),"") | H16: =IF(G16=0,"",G16*$H$5) | I16: =G16 -> 0 | J16: =IF(I16=0,"",I16-H16)
B17: =IF(A17="","",TEXT(A17,"DDDD")) | C17: =IF(A17<>"",TEXT(A17,"aaaa"),"") | D17: =IF(A17<>"",PROPER(TEXT(A17,"Mmmm")),"") | H17: =IF(G17=0,"",G17*$H$5) | I17: =G17 -> 0 | J17: =IF(I17=0,"",I17-H17)
B18: =IF(A18="","",TEXT(A18,"DDDD")) | C18: =IF(A18<>"",TEXT(A18,"aaaa"),"") | D18: =IF(A18<>"",PROPER(TEXT(A18,"Mmmm")),"") | H18: =IF(G18=0,"",G18*$H$5) | I18: =G18 -> 0 | J18: =IF(I18=0,"",I18-H18)
B19: =IF(A19="","",TEXT(A19,"DDDD")) | C19: =IF(A19<>"",TEXT(A19,"aaaa"),"") | D19: =IF(A19<>"",PROPER(TEXT(A19,"Mmmm")),"") | H19: =IF(G19=0,"",G19*$H$5) | I19: =G19 -> 0 | J19: =IF(I19=0,"",I19-H19)
B20: =IF(A20="","",TEXT(A20,"DDDD")) | C20: =IF(A20<>"",TEXT(A20,"aaaa"),"") | D20: =IF(A20<>"",PROPER(TEXT(A20,"Mmmm")),"") | H20: =IF(G20=0,"",G20*$H$5) | I20: =G20 -> 0 | J20: =IF(I20=0,"",I20-H20)
... B341: =IF(A341="","",TEXT(A341,"DDDD")) | C341: =IF(A341<>"",TEXT(A341,"aaaa"),"") | D341: =IF(A341<>"",PROPER(TEXT(A341,"Mmmm")),"") | H341: =IF(G341=0,"",G341*$H$5) | I341: =G341 -> 0 | J341: =IF(I341=0,"",I341-H341)
B342: =IF(A342="","",TEXT(A342,"DDDD")) | C342: =IF(A342<>"",TEXT(A342,"aaaa"),"") | D342: =IF(A342<>"",PROPER(TEXT(A342,"Mmmm")),"") | H342: =IF(G342=0,"",G342*$H$5) | I342: =IF(#REF!="","",#REF!+G342+#REF!+#REF!+#REF!+H342) -> #REF! | J342: =IF(I342=0,"",I342-H342) -> #REF!
B343: =IF(A343="","",TEXT(A343,"DDDD")) | C343: =IF(A343<>"",TEXT(A343,"aaaa"),"") | D343: =IF(A343<>"",PROPER(TEXT(A343,"Mmmm")),"") | H343: =IF(G343=0,"",G343*$H$5) | I343: =IF(#REF!="","",#REF!+G343+#REF!+#REF!+#REF!+H343) -> #REF! | J343: =IF(I343=0,"",I343-H343) -> #REF!
B344: =IF(A344="","",TEXT(A344,"DDDD")) | C344: =IF(A344<>"",TEXT(A344,"aaaa"),"") | D344: =IF(A344<>"",PROPER(TEXT(A344,"Mmmm")),"") | H344: =IF(G344=0,"",G344*$H$5) | I344: =IF(#REF!="","",#REF!+G344+#REF!+#REF!+#REF!+H344) -> #REF! | J344: =IF(I344=0,"",I344-H344) -> #REF!
B345: =IF(A345="","",TEXT(A345,"DDDD")) | C345: =IF(A345<>"",TEXT(A345,"aaaa"),"") | D345: =IF(A345<>"",PROPER(TEXT(A345,"Mmmm")),"") | H345: =IF(G345=0,"",G345*$H$5) | I345: =IF(#REF!="","",#REF!+G345+#REF!+#REF!+#REF!+H345) -> #REF! | J345: =IF(I345=0,"",I345-H345) -> #REF!
B346: =IF(A346="","",TEXT(A346,"DDDD")) | C346: =IF(A346<>"",TEXT(A346,"aaaa"),"") | D346: =IF(A346<>"",PROPER(TEXT(A346,"Mmmm")),"") | H346: =IF(G346=0,"",G346*$H$5) | I346: =IF(#REF!="","",#REF!+G346+#REF!+#REF!+#REF!+H346) -> #REF! | J346: =IF(I346=0,"",I346-H346) -> #REF!
B347: =IF(A347="","",TEXT(A347,"DDDD")) | C347: =IF(A347<>"",TEXT(A347,"aaaa"),"") | D347: =IF(A347<>"",PROPER(TEXT(A347,"Mmmm")),"") | H347: =IF(G347=0,"",G347*$H$5) | I347: =IF(#REF!="","",#REF!+G347+#REF!+#REF!+#REF!+H347) -> #REF! | J347: =IF(I347=0,"",I347-H347) -> #REF!
B348: =IF(A348="","",TEXT(A348,"DDDD")) | C348: =IF(A348<>"",TEXT(A348,"aaaa"),"") | D348: =IF(A348<>"",PROPER(TEXT(A348,"Mmmm")),"") | H348: =IF(G348=0,"",G348*$H$5) | I348: =IF(#REF!="","",#REF!+G348+#REF!+#REF!+#REF!+H348) -> #REF! | J348: =IF(I348=0,"",I348-H348) -> #REF!
B349: =IF(A349="","",TEXT(A349,"DDDD")) | C349: =IF(A349<>"",TEXT(A349,"aaaa"),"") | D349: =IF(A349<>"",PROPER(TEXT(A349,"Mmmm")),"") | H349: =IF(G349=0,"",G349*$H$5) | I349: =IF(#REF!="","",#REF!+G349+#REF!+#REF!+#REF!+H349) -> #REF! | J349: =IF(I349=0,"",I349-H349) -> #REF!
B350: =IF(A350="","",TEXT(A350,"DDDD")) | C350: =IF(A350<>"",TEXT(A350,"aaaa"),"") | D350: =IF(A350<>"",PROPER(TEXT(A350,"Mmmm")),"") | H350: =IF(G350=0,"",G350*$H$5) | I350: =IF(#REF!="","",#REF!+G350+#REF!+#REF!+#REF!+H350) -> #REF! | J350: =IF(I350=0,"",I350-H350) -> #REF!
B351: =IF(A351="","",TEXT(A351,"DDDD")) | C351: =IF(A351<>"",TEXT(A351,"aaaa"),"") | D351: =IF(A351<>"",PROPER(TEXT(A351,"Mmmm")),"") | H351: =IF(G351=0,"",G351*$H$5) | I351: =IF(#REF!="","",#REF!+G351+#REF!+#REF!+#REF!+H351) -> #REF! | J351: =IF(I351=0,"",I351-H351) -> #REF!
B352: =IF(A352="","",TEXT(A352,"DDDD")) | C352: =IF(A352<>"",TEXT(A352,"aaaa"),"") | D352: =IF(A352<>"",PROPER(TEXT(A352,"Mmmm")),"") | H352: =IF(G352=0,"",G352*$H$5) | I352: =IF(#REF!="","",#REF!+G352+#REF!+#REF!+#REF!+H352) -> #REF! | J352: =IF(I352=0,"",I352-H352) -> #REF!
B353: =IF(A353="","",TEXT(A353,"DDDD")) | C353: =IF(A353<>"",TEXT(A353,"aaaa"),"") | D353: =IF(A353<>"",PROPER(TEXT(A353,"Mmmm")),"") | H353: =IF(G353=0,"",G353*$H$5) | I353: =IF(#REF!="","",#REF!+G353+#REF!+#REF!+#REF!+H353) -> #REF! | J353: =IF(I353=0,"",I353-H353) -> #REF!
... B681: =IF(A681="","",TEXT(A681,"DDDD")) | C681: =IF(A681<>"",TEXT(A681,"aaaa"),"") | D681: =IF(A681<>"",PROPER(TEXT(A681,"Mmmm")),"") | H681: =IF(G681=0,"",G681*$H$5) | I681: =IF(#REF!="","",#REF!+G681+#REF!+#REF!+#REF!+H681) -> #REF! | J681: =IF(I681=0,"",I681-H681) -> #REF!
B682: =IF(A682="","",TEXT(A682,"DDDD")) | C682: =IF(A682<>"",TEXT(A682,"aaaa"),"") | D682: =IF(A682<>"",PROPER(TEXT(A682,"Mmmm")),"")
B683: =IF(A683="","",TEXT(A683,"DDDD")) | C683: =IF(A683<>"",TEXT(A683,"aaaa"),"") | D683: =IF(A683<>"",PROPER(TEXT(A683,"Mmmm")),"")
B684: =IF(A684="","",TEXT(A684,"DDDD")) | C684: =IF(A684<>"",TEXT(A684,"aaaa"),"") | D684: =IF(A684<>"",PROPER(TEXT(A684,"Mmmm")),"")
B685: =IF(A685="","",TEXT(A685,"DDDD")) | C685: =IF(A685<>"",TEXT(A685,"aaaa"),"") | D685: =IF(A685<>"",PROPER(TEXT(A685,"Mmmm")),"")
B686: =IF(A686="","",TEXT(A686,"DDDD")) | C686: =IF(A686<>"",TEXT(A686,"aaaa"),"") | D686: =IF(A686<>"",PROPER(TEXT(A686,"Mmmm")),"")
B687: =IF(A687="","",TEXT(A687,"DDDD")) | C687: =IF(A687<>"",TEXT(A687,"aaaa"),"") | D687: =IF(A687<>"",PROPER(TEXT(A687,"Mmmm")),"")
B688: =IF(A688="","",TEXT(A688,"DDDD")) | C688: =IF(A688<>"",TEXT(A688,"aaaa"),"") | D688: =IF(A688<>"",PROPER(TEXT(A688,"Mmmm")),"")
B689: =IF(A689="","",TEXT(A689,"DDDD")) | C689: =IF(A689<>"",TEXT(A689,"aaaa"),"") | D689: =IF(A689<>"",PROPER(TEXT(A689,"Mmmm")),"")
B690: =IF(A690="","",TEXT(A690,"DDDD")) | C690: =IF(A690<>"",TEXT(A690,"aaaa"),"") | D690: =IF(A690<>"",PROPER(TEXT(A690,"Mmmm")),"")
B691: =IF(A691="","",TEXT(A691,"DDDD")) | C691: =IF(A691<>"",TEXT(A691,"aaaa"),"") | D691: =IF(A691<>"",PROPER(TEXT(A691,"Mmmm")),"")
...

Sheet 💰Fluxo de Pagamentos
G1: PREVISÃO FLUXO DE PAGAMENTO | I1: SALDO ATUAL
B2: CONTAS A PAGAR | G2: De: | H2: Até: | I2: 0
B3: HOJE | C3: =IFERROR(SUMIFS('📋 Despesas'!$K:$K,'📋 Despesas'!$N:$N,E3),"S/D") -> 0 | D3: =TEXT(WEEKDAY(E3),"dddd") -> quarta-feira | E3: =TODAY() -> 46190 | G3: 46174 | H3: 46203 | I3: SALDO FINAL
B4: AMANHA | C4: =IFERROR(SUMIFS('📋 Despesas'!$K:$K,'📋 Despesas'!$N:$N,E4),"S/D") -> 0 | D4: =TEXT(WEEKDAY(E4),"dddd") -> quinta-feira | E4: =E3+1 -> 46191 | G4: VALOR A PAGAR: | H4: =SUMIFS('📋 Despesas'!J7:J17825,'📋 Despesas'!N7:N17825,">="&G3,'📋 Despesas'!N7:N17825,"<="&H3) -> 4430.03 | I4: =I2-H4 -> -4430.03
B5: DAQUI 2 DIAS | C5: =IFERROR(SUMIFS('📋 Despesas'!$K:$K,'📋 Despesas'!$N:$N,E5),"S/D") -> 0 | D5: =TEXT(WEEKDAY(E5),"dddd") -> sexta-feira | E5: =E4+1 -> 46192
B6: DAQUI 3 DIAS | C6: =IFERROR(SUMIFS('📋 Despesas'!$K:$K,'📋 Despesas'!$N:$N,E6),"S/D") -> 0 | D6: =TEXT(WEEKDAY(E6),"dddd") -> sábado | E6: =E5+1 -> 46193 | G6: Receitas do Mês | H6: =SUMIFS('💸 Receitas'!J7:J300307,'💸 Receitas'!A7:A300307,">="&G3,'💸 Receitas'!A7:A300307,"<="&H3) -> 10500
B7: DAQUI 4 DIAS | C7: =IFERROR(SUMIFS('📋 Despesas'!$K:$K,'📋 Despesas'!$N:$N,E7),"S/D") -> 0 | D7: =TEXT(WEEKDAY(E7),"dddd") -> domingo | E7: =E6+1 -> 46194 | G7: Saldo Atual: | H7: =I4+H6 -> 6069.97
B8: DAQUI 5 DIAS | C8: =IFERROR(SUMIFS('📋 Despesas'!$K:$K,'📋 Despesas'!$N:$N,E8),"S/D") -> 0 | D8: =TEXT(WEEKDAY(E8),"dddd") -> segunda-feira | E8: =E7+1 -> 46195 | G8: Crédito RECEITA Cartão: | H8: 0
B9: DAQUI 6 DIAS | C9: =IFERROR(SUMIFS('📋 Despesas'!$K:$K,'📋 Despesas'!$N:$N,E9),"S/D") -> 0 | D9: =TEXT(WEEKDAY(E9),"dddd") -> terça-feira | E9: =E8+1 -> 46196 | G9: Depósitos $ mês ante | H9: 0
B10: DAQUI 7 DIAS | C10: =IFERROR(SUMIFS('📋 Despesas'!$K:$K,'📋 Despesas'!$N:$N,E10),"S/D") -> 0 | D10: =TEXT(WEEKDAY(E10),"dddd") -> quarta-feira | E10: =E9+1 -> 46197 | G10: Saldo Futuro | H10: =H7+H8+H9 -> 6069.97 | K10: =I2-(SUMIFS('📋 Despesas'!M7:M8183,'📋 Despesas'!N7:N8183,">="&G3,'📋 Despesas'!N7:N8183,"<="&H11))+H8+H9+H6 -> 10500
G11: DADOS PARA FILTRO: | H11: 46082 | I11: =SUBTOTAL(9,L12:L777) -> 0
G12: {=IFERROR(_xlfn._xlws.FILTER('📋 Despesas'!E7:J17825, ('📋 Despesas'!N7:N17825=H11) * ('📋 Despesas'!K7:K17825>0)),"Sem Pgto")} -> Sem Pgto
D13: =H4-E13 -> 810.03 | E13: ='📋 Despesas'!K4 -> 3620
B14: Fluxo de Pagamento Diarios
B15: Data | C15: Dia / semana | D15: Valor
B16: 45839 | C16: =IF(B16<>"",TEXT(WEEKDAY(B16),"dddd"),"") -> terça-feira | D16: =SUMIFS('📋 Despesas'!M:M,'📋 Despesas'!N:N,B16) -> 0
B17: 45840 | C17: =IF(B17<>"",TEXT(WEEKDAY(B17),"dddd"),"") -> quarta-feira | D17: =SUMIFS('📋 Despesas'!M:M,'📋 Despesas'!N:N,B17) -> 0
B18: 45841 | C18: =IF(B18<>"",TEXT(WEEKDAY(B18),"dddd"),"") -> quinta-feira | D18: =SUMIFS('📋 Despesas'!M:M,'📋 Despesas'!N:N,B18) -> 0
B19: 45842 | C19: =IF(B19<>"",TEXT(WEEKDAY(B19),"dddd"),"") -> sexta-feira | D19: =SUMIFS('📋 Despesas'!M:M,'📋 Despesas'!N:N,B19) -> 0
B20: 45843 | C20: =IF(B20<>"",TEXT(WEEKDAY(B20),"dddd"),"") -> sábado | D20: =SUMIFS('📋 Despesas'!M:M,'📋 Despesas'!N:N,B20) -> 0
B21: 45844 | C21: =IF(B21<>"",TEXT(WEEKDAY(B21),"dddd"),"") -> domingo | D21: =SUMIFS('📋 Despesas'!M:M,'📋 Despesas'!N:N,B21) -> 0
B22: 45845 | C22: =IF(B22<>"",TEXT(WEEKDAY(B22),"dddd"),"") -> segunda-feira | D22: =SUMIFS('📋 Despesas'!M:M,'📋 Despesas'!N:N,B22) -> 0
B23: 45846 | C23: =IF(B23<>"",TEXT(WEEKDAY(B23),"dddd"),"") -> terça-feira | D23: =SUMIFS('📋 Despesas'!M:M,'📋 Despesas'!N:N,B23) -> 0
B24: 45847 | C24: =IF(B24<>"",TEXT(WEEKDAY(B24),"dddd"),"") -> quarta-feira | D24: =SUMIFS('📋 Despesas'!M:M,'📋 Despesas'!N:N,B24) -> 0
B25: 45848 | C25: =IF(B25<>"",TEXT(WEEKDAY(B25),"dddd"),"") -> quinta-feira | D25: =SUMIFS('📋 Despesas'!M:M,'📋 Despesas'!N:N,B25) -> 0
B26: 45849 | C26: =IF(B26<>"",TEXT(WEEKDAY(B26),"dddd"),"") -> sexta-feira | D26: =SUMIFS('📋 Despesas'!M:M,'📋 Despesas'!N:N,B26) -> 0
B27: 45850 | C27: =IF(B27<>"",TEXT(WEEKDAY(B27),"dddd"),"") -> sábado | D27: =SUMIFS('📋 Despesas'!M:M,'📋 Despesas'!N:N,B27) -> 0
... B46: 45869 | C46: =IF(B46<>"",TEXT(WEEKDAY(B46),"dddd"),"") -> quinta-feira | D46: =SUMIFS('📋 Despesas'!M:M,'📋 Despesas'!N:N,B46) -> 0
B47: 45870 | C47: =IF(B47<>"",TEXT(WEEKDAY(B47),"dddd"),"") -> sexta-feira | D47: =SUMIFS('📋 Despesas'!K:K,'📋 Despesas'!N:N,B47) -> 0
B48: 45871 | C48: =IF(B48<>"",TEXT(WEEKDAY(B48),"dddd"),"") -> sábado | D48: =SUMIFS('📋 Despesas'!K:K,'📋 Despesas'!N:N,B48) -> 0
B49: 45872 | C49: =IF(B49<>"",TEXT(WEEKDAY(B49),"dddd"),"") -> domingo | D49: =SUMIFS('📋 Despesas'!K:K,'📋 Despesas'!N:N,B49) -> 0
B50: 45873 | C50: =IF(B50<>"",TEXT(WEEKDAY(B50),"dddd"),"") -> segunda-feira | D50: =SUMIFS('📋 Despesas'!K:K,'📋 Despesas'!N:N,B50) -> 0
B51: 45874 | C51: =IF(B51<>"",TEXT(WEEKDAY(B51),"dddd"),"") -> terça-feira | D51: =SUMIFS('📋 Despesas'!K:K,'📋 Despesas'!N:N,B51) -> 0
B52: 45875 | C52: =IF(B52<>"",TEXT(WEEKDAY(B52),"dddd"),"") -> quarta-feira | D52: =SUMIFS('📋 Despesas'!K:K,'📋 Despesas'!N:N,B52) -> 0
B53: 45876 | C53: =IF(B53<>"",TEXT(WEEKDAY(B53),"dddd"),"") -> quinta-feira | D53: =SUMIFS('📋 Despesas'!K:K,'📋 Despesas'!N:N,B53) -> 0
B54: 45877 | C54: =IF(B54<>"",TEXT(WEEKDAY(B54),"dddd"),"") -> sexta-feira | D54: =SUMIFS('📋 Despesas'!K:K,'📋 Despesas'!N:N,B54) -> 0
B55: 45878 | C55: =IF(B55<>"",TEXT(WEEKDAY(B55),"dddd"),"") -> sábado | D55: =SUMIFS('📋 Despesas'!K:K,'📋 Despesas'!N:N,B55) -> 0
B56: 45879 | C56: =IF(B56<>"",TEXT(WEEKDAY(B56),"dddd"),"") -> domingo | D56: =SUMIFS('📋 Despesas'!K:K,'📋 Despesas'!N:N,B56) -> 0
B57: 45880 | C57: =IF(B57<>"",TEXT(WEEKDAY(B57),"dddd"),"") -> segunda-feira | D57: =SUMIFS('📋 Despesas'!K:K,'📋 Despesas'!N:N,B57) -> 0
B58: 45881 | C58: =IF(B58<>"",TEXT(WEEKDAY(B58),"dddd"),"") -> terça-feira | D58: =SUMIFS('📋 Despesas'!K:K,'📋 Despesas'!N:N,B58) -> 0
...

Sheet 📈Det. Resultados
B2: DETALHAMENTO DE RESULTADO | D2: =$C$3 -> 2026 | E2: =$C$3 -> 2026 | F2: =$C$3 -> 2026 | G2: =$C$3 -> 2026 | H2: =$C$3 -> 2026 | I2: =$C$3 -> 2026 | J2: =$C$3 -> 2026 | K2: =$C$3 -> 2026 | ... O2: =$C$3 -> 2026
B3: *Alterar ano no dashboard --> | C3: 2026 | D3: JANEIRO | E3: FEVEREIRO | F3: MARÇO | G3: ABRIL | H3: MAIO | I3: JUNHO | J3: JULHO | K3: AGOSTO | L3: SETEMBRO | M3: OUTUBRO | N3: NOVEMBRO | O3: DEZEMBRO
B4: FAT. BRUTO | C4: =SUMIFS($D4:$Q4,$D$2:$Q$2,$C$3) -> 10500 | D4: ='🏭 DRE'!D6 -> 0 | E4: ='🏭 DRE'!E6 -> 0 | F4: ='🏭 DRE'!F6 -> 0 | G4: ='🏭 DRE'!G6 -> 0 | H4: ='🏭 DRE'!H6 -> 0 | I4: ='🏭 DRE'!I6 -> 10500 | J4: ='🏭 DRE'!J6 -> 0 | K4: ='🏭 DRE'!K6 -> 0 | ... O4: ='🏭 DRE'!O6 -> 0
B5: IMPOSTOS / TAXAS | C5: =SUMIFS($D5:$Q5,$D$2:$Q$2,$C$3) -> 0 | D5: =D4-D6 -> 0 | E5: =E4-E6 -> 0 | F5: =F4-F6 -> 0 | G5: =G4-G6 -> 0 | H5: =H4-H6 -> 0 | I5: =I4-I6 -> 0 | J5: =J4-J6 -> 0 | K5: =K4-K6 -> 0 | ... O5: =O4-O6 -> 0
B6: FAT. LIQUIDO | C6: =SUMIFS($D6:$Q6,$D$2:$Q$2,$C$3) -> 10500 | D6: =SUMIFS('💸 Receitas'!$J$7:$J$681,'💸 Receitas'!$C$7:$C$681,D$2,'💸 Receitas'!$D$7:$D$681,'🏭 DRE'!D5) -> 0 | E6: =SUMIFS('💸 Receitas'!$J$7:$J$681,'💸 Receitas'!$C$7:$C$681,E$2,'💸 Receitas'!$D$7:$D$681,'🏭 DRE'!E5) -> 0 | F6: =SUMIFS('💸 Receitas'!$J$7:$J$681,'💸 Receitas'!$C$7:$C$681,F$2,'💸 Receitas'!$D$7:$D$681,'🏭 DRE'!F5) -> 0 | G6: =SUMIFS('💸 Receitas'!$J$7:$J$681,'💸 Receitas'!$C$7:$C$681,G$2,'💸 Receitas'!$D$7:$D$681,'🏭 DRE'!G5) -> 0 | H6: =SUMIFS('💸 Receitas'!$J$7:$J$681,'💸 Receitas'!$C$7:$C$681,H$2,'💸 Receitas'!$D$7:$D$681,'🏭 DRE'!H5) -> 0 | I6: =SUMIFS('💸 Receitas'!$J$7:$J$681,'💸 Receitas'!$C$7:$C$681,I$2,'💸 Receitas'!$D$7:$D$681,'🏭 DRE'!I5) -> 10500 | J6: =SUMIFS('💸 Receitas'!$J$7:$J$681,'💸 Receitas'!$C$7:$C$681,J$2,'💸 Receitas'!$D$7:$D$681,'🏭 DRE'!J5) -> 0 | K6: =SUMIFS('💸 Receitas'!$J$7:$J$681,'💸 Receitas'!$C$7:$C$681,K$2,'💸 Receitas'!$D$7:$D$681,'🏭 DRE'!K5) -> 0 | ... O6: =SUMIFS('💸 Receitas'!$J$7:$J$681,'💸 Receitas'!$C$7:$C$681,O$2,'💸 Receitas'!$D$7:$D$681,'🏭 DRE'!O5) -> 0
B7: DESPESAS TOTAIS | C7: =SUMIFS($D7:$Q7,$D$2:$Q$2,$C$3) -> 10757.95 | D7: =SUM(D8:D27) -> 0 | E7: =SUM(E8:E27) -> 0 | F7: =SUM(F8:F27) -> 0 | G7: =SUM(G8:G27) -> 0 | H7: =SUM(H8:H27) -> 1840.36 | I7: =SUM(I8:I27) -> 4227.59 | J7: =SUM(J8:J27) -> 4690 | K7: =SUM(K8:K27) -> 0 | ... O7: =SUM(O8:O27) -> 0
B9: PROLABORE | C9: =SUM(D9:O9) -> 7422.92 | D9: =SUMIFS('📋 Despesas'!$J$7:$J$17825,'📋 Despesas'!$F$7:$F$17825,$B9,'📋 Despesas'!$C$7:$C$17825,D$3,'📋 Despesas'!$D$7:$D$17825,D$2) -> 0 | E9: =SUMIFS('📋 Despesas'!$J$7:$J$17825,'📋 Despesas'!$F$7:$F$17825,$B9,'📋 Despesas'!$C$7:$C$17825,E$3,'📋 Despesas'!$D$7:$D$17825,E$2) -> 0 | F9: =SUMIFS('📋 Despesas'!$J$7:$J$17825,'📋 Despesas'!$F$7:$F$17825,$B9,'📋 Despesas'!$C$7:$C$17825,F$3,'📋 Despesas'!$D$7:$D$17825,F$2) -> 0 | G9: =SUMIFS('📋 Despesas'!$J$7:$J$17825,'📋 Despesas'!$F$7:$F$17825,$B9,'📋 Despesas'!$C$7:$C$17825,G$3,'📋 Despesas'!$D$7:$D$17825,G$2) -> 0 | H9: =SUMIFS('📋 Despesas'!$J$7:$J$17825,'📋 Despesas'!$F$7:$F$17825,$B9,'📋 Despesas'!$C$7:$C$17825,H$3,'📋 Despesas'!$D$7:$D$17825,H$2) -> 1637.92 | I9: =SUMIFS('📋 Despesas'!$J$7:$J$17825,'📋 Despesas'!$F$7:$F$17825,$B9,'📋 Despesas'!$C$7:$C$17825,I$3,'📋 Despesas'!$D$7:$D$17825,I$2) -> 2670 | J9: =SUMIFS('📋 Despesas'!$J$7:$J$17825,'📋 Despesas'!$F$7:$F$17825,$B9,'📋 Despesas'!$C$7:$C$17825,J$3,'📋 Despesas'!$D$7:$D$17825,J$2) -> 3115 | K9: =SUMIFS('📋 Despesas'!$J$7:$J$17825,'📋 Despesas'!$F$7:$F$17825,$B9,'📋 Despesas'!$C$7:$C$17825,K$3,'📋 Despesas'!$D$7:$D$17825,K$2) -> 0 | ... O9: =SUMIFS('📋 Despesas'!$J$7:$J$17825,'📋 Despesas'!$F$7:$F$17825,$B9,'📋 Despesas'!$C$7:$C$17825,O$3,'📋 Despesas'!$D$7:$D$17825,O$2) -> 0 | Q9: {=_xlfn._xlws.FILTER($B$9:$B$27,$B$9:$B$27<>"")} -> PROLABORE
B10: INSS | C10: =SUM(D10:O10) -> 917.44 | D10: =SUMIFS('📋 Despesas'!$J$7:$J$17825,'📋 Despesas'!$F$7:$F$17825,$B10,'📋 Despesas'!$C$7:$C$17825,D$3,'📋 Despesas'!$D$7:$D$17825,D$2) -> 0 | E10: =SUMIFS('📋 Despesas'!$J$7:$J$17825,'📋 Despesas'!$F$7:$F$17825,$B10,'📋 Despesas'!$C$7:$C$17825,E$3,'📋 Despesas'!$D$7:$D$17825,E$2) -> 0 | F10: =SUMIFS('📋 Despesas'!$J$7:$J$17825,'📋 Despesas'!$F$7:$F$17825,$B10,'📋 Despesas'!$C$7:$C$17825,F$3,'📋 Despesas'!$D$7:$D$17825,F$2) -> 0 | G10: =SUMIFS('📋 Despesas'!$J$7:$J$17825,'📋 Despesas'!$F$7:$F$17825,$B10,'📋 Despesas'!$C$7:$C$17825,G$3,'📋 Despesas'!$D$7:$D$17825,G$2) -> 0 | H10: =SUMIFS('📋 Despesas'!$J$7:$J$17825,'📋 Despesas'!$F$7:$F$17825,$B10,'📋 Despesas'!$C$7:$C$17825,H$3,'📋 Despesas'!$D$7:$D$17825,H$2) -> 202.44 | I10: =SUMIFS('📋 Despesas'!$J$7:$J$17825,'📋 Despesas'!$F$7:$F$17825,$B10,'📋 Despesas'!$C$7:$C$17825,I$3,'📋 Despesas'!$D$7:$D$17825,I$2) -> 330 | J10: =SUMIFS('📋 Despesas'!$J$7:$J$17825,'📋 Despesas'!$F$7:$F$17825,$B10,'📋 Despesas'!$C$7:$C$17825,J$3,'📋 Despesas'!$D$7:$D$17825,J$2) -> 385 | K10: =SUMIFS('📋 Despesas'!$J$7:$J$17825,'📋 Despesas'!$F$7:$F$17825,$B10,'📋 Despesas'!$C$7:$C$17825,K$3,'📋 Despesas'!$D$7:$D$17825,K$2) -> 0 | ... O10: =SUMIFS('📋 Despesas'!$J$7:$J$17825,'📋 Despesas'!$F$7:$F$17825,$B10,'📋 Despesas'!$C$7:$C$17825,O$3,'📋 Despesas'!$D$7:$D$17825,O$2) -> 0 | Q10: INSS
B11: LUCRO | C11: =SUM(D11:O11) -> 0 | D11: =SUMIFS('📋 Despesas'!$J$7:$J$17825,'📋 Despesas'!$F$7:$F$17825,$B11,'📋 Despesas'!$C$7:$C$17825,D$3,'📋 Despesas'!$D$7:$D$17825,D$2) -> 0 | E11: =SUMIFS('📋 Despesas'!$J$7:$J$17825,'📋 Despesas'!$F$7:$F$17825,$B11,'📋 Despesas'!$C$7:$C$17825,E$3,'📋 Despesas'!$D$7:$D$17825,E$2) -> 0 | F11: =SUMIFS('📋 Despesas'!$J$7:$J$17825,'📋 Despesas'!$F$7:$F$17825,$B11,'📋 Despesas'!$C$7:$C$17825,F$3,'📋 Despesas'!$D$7:$D$17825,F$2) -> 0 | G11: =SUMIFS('📋 Despesas'!$J$7:$J$17825,'📋 Despesas'!$F$7:$F$17825,$B11,'📋 Despesas'!$C$7:$C$17825,G$3,'📋 Despesas'!$D$7:$D$17825,G$2) -> 0 | H11: =SUMIFS('📋 Despesas'!$J$7:$J$17825,'📋 Despesas'!$F$7:$F$17825,$B11,'📋 Despesas'!$C$7:$C$17825,H$3,'📋 Despesas'!$D$7:$D$17825,H$2) -> 0 | I11: =SUMIFS('📋 Despesas'!$J$7:$J$17825,'📋 Despesas'!$F$7:$F$17825,$B11,'📋 Despesas'!$C$7:$C$17825,I$3,'📋 Despesas'!$D$7:$D$17825,I$2) -> 0 | J11: =SUMIFS('📋 Despesas'!$J$7:$J$17825,'📋 Despesas'!$F$7:$F$17825,$B11,'📋 Despesas'!$C$7:$C$17825,J$3,'📋 Despesas'!$D$7:$D$17825,J$2) -> 0 | K11: =SUMIFS('📋 Despesas'!$J$7:$J$17825,'📋 Despesas'!$F$7:$F$17825,$B11,'📋 Despesas'!$C$7:$C$17825,K$3,'📋 Despesas'!$D$7:$D$17825,K$2) -> 0 | ... O11: =SUMIFS('📋 Despesas'!$J$7:$J$17825,'📋 Despesas'!$F$7:$F$17825,$B11,'📋 Despesas'!$C$7:$C$17825,O$3,'📋 Despesas'!$D$7:$D$17825,O$2) -> 0 | Q11: LUCRO
B12: CONTABILIDADE | C12: =SUM(D12:O12) -> 1540 | D12: =SUMIFS('📋 Despesas'!$J$7:$J$17825,'📋 Despesas'!$F$7:$F$17825,$B12,'📋 Despesas'!$C$7:$C$17825,D$3,'📋 Despesas'!$D$7:$D$17825,D$2) -> 0 | E12: =SUMIFS('📋 Despesas'!$J$7:$J$17825,'📋 Despesas'!$F$7:$F$17825,$B12,'📋 Despesas'!$C$7:$C$17825,E$3,'📋 Despesas'!$D$7:$D$17825,E$2) -> 0 | F12: =SUMIFS('📋 Despesas'!$J$7:$J$17825,'📋 Despesas'!$F$7:$F$17825,$B12,'📋 Despesas'!$C$7:$C$17825,F$3,'📋 Despesas'!$D$7:$D$17825,F$2) -> 0 | G12: =SUMIFS('📋 Despesas'!$J$7:$J$17825,'📋 Despesas'!$F$7:$F$17825,$B12,'📋 Despesas'!$C$7:$C$17825,G$3,'📋 Despesas'!$D$7:$D$17825,G$2) -> 0 | H12: =SUMIFS('📋 Despesas'!$J$7:$J$17825,'📋 Despesas'!$F$7:$F$17825,$B12,'📋 Despesas'!$C$7:$C$17825,H$3,'📋 Despesas'!$D$7:$D$17825,H$2) -> 0 | I12: =SUMIFS('📋 Despesas'!$J$7:$J$17825,'📋 Despesas'!$F$7:$F$17825,$B12,'📋 Despesas'!$C$7:$C$17825,I$3,'📋 Despesas'!$D$7:$D$17825,I$2) -> 950 | J12: =SUMIFS('📋 Despesas'!$J$7:$J$17825,'📋 Despesas'!$F$7:$F$17825,$B12,'📋 Despesas'!$C$7:$C$17825,J$3,'📋 Despesas'!$D$7:$D$17825,J$2) -> 590 | K12: =SUMIFS('📋 Despesas'!$J$7:$J$17825,'📋 Despesas'!$F$7:$F$17825,$B12,'📋 Despesas'!$C$7:$C$17825,K$3,'📋 Despesas'!$D$7:$D$17825,K$2) -> 0 | ... O12: =SUMIFS('📋 Despesas'!$J$7:$J$17825,'📋 Despesas'!$F$7:$F$17825,$B12,'📋 Despesas'!$C$7:$C$17825,O$3,'📋 Despesas'!$D$7:$D$17825,O$2) -> 0 | Q12: CONTABILIDADE
B13: OUTROS | C13: =SUM(D13:O13) -> 0 | D13: =SUMIFS('📋 Despesas'!$J$7:$J$17825,'📋 Despesas'!$F$7:$F$17825,$B13,'📋 Despesas'!$C$7:$C$17825,D$3,'📋 Despesas'!$D$7:$D$17825,D$2) -> 0 | E13: =SUMIFS('📋 Despesas'!$J$7:$J$17825,'📋 Despesas'!$F$7:$F$17825,$B13,'📋 Despesas'!$C$7:$C$17825,E$3,'📋 Despesas'!$D$7:$D$17825,E$2) -> 0 | F13: =SUMIFS('📋 Despesas'!$J$7:$J$17825,'📋 Despesas'!$F$7:$F$17825,$B13,'📋 Despesas'!$C$7:$C$17825,F$3,'📋 Despesas'!$D$7:$D$17825,F$2) -> 0 | G13: =SUMIFS('📋 Despesas'!$J$7:$J$17825,'📋 Despesas'!$F$7:$F$17825,$B13,'📋 Despesas'!$C$7:$C$17825,G$3,'📋 Despesas'!$D$7:$D$17825,G$2) -> 0 | H13: =SUMIFS('📋 Despesas'!$J$7:$J$17825,'📋 Despesas'!$F$7:$F$17825,$B13,'📋 Despesas'!$C$7:$C$17825,H$3,'📋 Despesas'!$D$7:$D$17825,H$2) -> 0 | I13: =SUMIFS('📋 Despesas'!$J$7:$J$17825,'📋 Despesas'!$F$7:$F$17825,$B13,'📋 Despesas'!$C$7:$C$17825,I$3,'📋 Despesas'!$D$7:$D$17825,I$2) -> 0 | J13: =SUMIFS('📋 Despesas'!$J$7:$J$17825,'📋 Despesas'!$F$7:$F$17825,$B13,'📋 Despesas'!$C$7:$C$17825,J$3,'📋 Despesas'!$D$7:$D$17825,J$2) -> 0 | K13: =SUMIFS('📋 Despesas'!$J$7:$J$17825,'📋 Despesas'!$F$7:$F$17825,$B13,'📋 Despesas'!$C$7:$C$17825,K$3,'📋 Despesas'!$D$7:$D$17825,K$2) -> 0 | ... O13: =SUMIFS('📋 Despesas'!$J$7:$J$17825,'📋 Despesas'!$F$7:$F$17825,$B13,'📋 Despesas'!$C$7:$C$17825,O$3,'📋 Despesas'!$D$7:$D$17825,O$2) -> 0 | Q13: OUTROS
B14: ADM | C14: =SUM(D14:O14) -> 277.59 | D14: =SUMIFS('📋 Despesas'!$J$7:$J$17825,'📋 Despesas'!$F$7:$F$17825,$B14,'📋 Despesas'!$C$7:$C$17825,D$3,'📋 Despesas'!$D$7:$D$17825,D$2) -> 0 | E14: =SUMIFS('📋 Despesas'!$J$7:$J$17825,'📋 Despesas'!$F$7:$F$17825,$B14,'📋 Despesas'!$C$7:$C$17825,E$3,'📋 Despesas'!$D$7:$D$17825,E$2) -> 0 | F14: =SUMIFS('📋 Despesas'!$J$7:$J$17825,'📋 Despesas'!$F$7:$F$17825,$B14,'📋 Despesas'!$C$7:$C$17825,F$3,'📋 Despesas'!$D$7:$D$17825,F$2) -> 0 | G14: =SUMIFS('📋 Despesas'!$J$7:$J$17825,'📋 Despesas'!$F$7:$F$17825,$B14,'📋 Despesas'!$C$7:$C$17825,G$3,'📋 Despesas'!$D$7:$D$17825,G$2) -> 0 | H14: =SUMIFS('📋 Despesas'!$J$7:$J$17825,'📋 Despesas'!$F$7:$F$17825,$B14,'📋 Despesas'!$C$7:$C$17825,H$3,'📋 Despesas'!$D$7:$D$17825,H$2) -> 0 | I14: =SUMIFS('📋 Despesas'!$J$7:$J$17825,'📋 Despesas'!$F$7:$F$17825,$B14,'📋 Despesas'!$C$7:$C$17825,I$3,'📋 Despesas'!$D$7:$D$17825,I$2) -> 277.59 | J14: =SUMIFS('📋 Despesas'!$J$7:$J$17825,'📋 Despesas'!$F$7:$F$17825,$B14,'📋 Despesas'!$C$7:$C$17825,J$3,'📋 Despesas'!$D$7:$D$17825,J$2) -> 0 | K14: =SUMIFS('📋 Despesas'!$J$7:$J$17825,'📋 Despesas'!$F$7:$F$17825,$B14,'📋 Despesas'!$C$7:$C$17825,K$3,'📋 Despesas'!$D$7:$D$17825,K$2) -> 0 | ... O14: =SUMIFS('📋 Despesas'!$J$7:$J$17825,'📋 Despesas'!$F$7:$F$17825,$B14,'📋 Despesas'!$C$7:$C$17825,O$3,'📋 Despesas'!$D$7:$D$17825,O$2) -> 0 | Q14: ADM
C15: =SUM(D15:O15) -> 0 | D15: =SUMIFS('📋 Despesas'!$J$7:$J$17825,'📋 Despesas'!$F$7:$F$17825,$B15,'📋 Despesas'!$C$7:$C$17825,D$3,'📋 Despesas'!$D$7:$D$17825,D$2) -> 0 | E15: =SUMIFS('📋 Despesas'!$J$7:$J$17825,'📋 Despesas'!$F$7:$F$17825,$B15,'📋 Despesas'!$C$7:$C$17825,E$3,'📋 Despesas'!$D$7:$D$17825,E$2) -> 0 | F15: =SUMIFS('📋 Despesas'!$J$7:$J$17825,'📋 Despesas'!$F$7:$F$17825,$B15,'📋 Despesas'!$C$7:$C$17825,F$3,'📋 Despesas'!$D$7:$D$17825,F$2) -> 0 | G15: =SUMIFS('📋 Despesas'!$J$7:$J$17825,'📋 Despesas'!$F$7:$F$17825,$B15,'📋 Despesas'!$C$7:$C$17825,G$3,'📋 Despesas'!$D$7:$D$17825,G$2) -> 0 | H15: =SUMIFS('📋 Despesas'!$J$7:$J$17825,'📋 Despesas'!$F$7:$F$17825,$B15,'📋 Despesas'!$C$7:$C$17825,H$3,'📋 Despesas'!$D$7:$D$17825,H$2) -> 0 | I15: =SUMIFS('📋 Despesas'!$J$7:$J$17825,'📋 Despesas'!$F$7:$F$17825,$B15,'📋 Despesas'!$C$7:$C$17825,I$3,'📋 Despesas'!$D$7:$D$17825,I$2) -> 0 | J15: =SUMIFS('📋 Despesas'!$J$7:$J$17825,'📋 Despesas'!$F$7:$F$17825,$B15,'📋 Despesas'!$C$7:$C$17825,J$3,'📋 Despesas'!$D$7:$D$17825,J$2) -> 0 | K15: =SUMIFS('📋 Despesas'!$J$7:$J$17825,'📋 Despesas'!$F$7:$F$17825,$B15,'📋 Despesas'!$C$7:$C$17825,K$3,'📋 Despesas'!$D$7:$D$17825,K$2) -> 0 | ... O15: =SUMIFS('📋 Despesas'!$J$7:$J$17825,'📋 Despesas'!$F$7:$F$17825,$B15,'📋 Despesas'!$C$7:$C$17825,O$3,'📋 Despesas'!$D$7:$D$17825,O$2) -> 0 | Q15: DAS
C16: =SUM(D16:O16) -> 0 | D16: =SUMIFS('📋 Despesas'!$J$7:$J$17825,'📋 Despesas'!$F$7:$F$17825,$B16,'📋 Despesas'!$C$7:$C$17825,D$3,'📋 Despesas'!$D$7:$D$17825,D$2) -> 0 | E16: =SUMIFS('📋 Despesas'!$J$7:$J$17825,'📋 Despesas'!$F$7:$F$17825,$B16,'📋 Despesas'!$C$7:$C$17825,E$3,'📋 Despesas'!$D$7:$D$17825,E$2) -> 0 | F16: =SUMIFS('📋 Despesas'!$J$7:$J$17825,'📋 Despesas'!$F$7:$F$17825,$B16,'📋 Despesas'!$C$7:$C$17825,F$3,'📋 Despesas'!$D$7:$D$17825,F$2) -> 0 | G16: =SUMIFS('📋 Despesas'!$J$7:$J$17825,'📋 Despesas'!$F$7:$F$17825,$B16,'📋 Despesas'!$C$7:$C$17825,G$3,'📋 Despesas'!$D$7:$D$17825,G$2) -> 0 | H16: =SUMIFS('📋 Despesas'!$J$7:$J$17825,'📋 Despesas'!$F$7:$F$17825,$B16,'📋 Despesas'!$C$7:$C$17825,H$3,'📋 Despesas'!$D$7:$D$17825,H$2) -> 0 | I16: =SUMIFS('📋 Despesas'!$J$7:$J$17825,'📋 Despesas'!$F$7:$F$17825,$B16,'📋 Despesas'!$C$7:$C$17825,I$3,'📋 Despesas'!$D$7:$D$17825,I$2) -> 0 | J16: =SUMIFS('📋 Despesas'!$J$7:$J$17825,'📋 Despesas'!$F$7:$F$17825,$B16,'📋 Despesas'!$C$7:$C$17825,J$3,'📋 Despesas'!$D$7:$D$17825,J$2) -> 0 | K16: =SUMIFS('📋 Despesas'!$J$7:$J$17825,'📋 Despesas'!$F$7:$F$17825,$B16,'📋 Despesas'!$C$7:$C$17825,K$3,'📋 Despesas'!$D$7:$D$17825,K$2) -> 0 | ... O16: =SUMIFS('📋 Despesas'!$J$7:$J$17825,'📋 Despesas'!$F$7:$F$17825,$B16,'📋 Despesas'!$C$7:$C$17825,O$3,'📋 Despesas'!$D$7:$D$17825,O$2) -> 0 | Q16: TAXAS
C17: =SUM(D17:O17) -> 0 | D17: =SUMIFS('📋 Despesas'!$J$7:$J$17825,'📋 Despesas'!$F$7:$F$17825,$B17,'📋 Despesas'!$C$7:$C$17825,D$3,'📋 Despesas'!$D$7:$D$17825,D$2) -> 0 | E17: =SUMIFS('📋 Despesas'!$J$7:$J$17825,'📋 Despesas'!$F$7:$F$17825,$B17,'📋 Despesas'!$C$7:$C$17825,E$3,'📋 Despesas'!$D$7:$D$17825,E$2) -> 0 | F17: =SUMIFS('📋 Despesas'!$J$7:$J$17825,'📋 Despesas'!$F$7:$F$17825,$B17,'📋 Despesas'!$C$7:$C$17825,F$3,'📋 Despesas'!$D$7:$D$17825,F$2) -> 0 | G17: =SUMIFS('📋 Despesas'!$J$7:$J$17825,'📋 Despesas'!$F$7:$F$17825,$B17,'📋 Despesas'!$C$7:$C$17825,G$3,'📋 Despesas'!$D$7:$D$17825,G$2) -> 0 | H17: =SUMIFS('📋 Despesas'!$J$7:$J$17825,'📋 Despesas'!$F$7:$F$17825,$B17,'📋 Despesas'!$C$7:$C$17825,H$3,'📋 Despesas'!$D$7:$D$17825,H$2) -> 0 | I17: =SUMIFS('📋 Despesas'!$J$7:$J$17825,'📋 Despesas'!$F$7:$F$17825,$B17,'📋 Despesas'!$C$7:$C$17825,I$3,'📋 Despesas'!$D$7:$D$17825,I$2) -> 0 | J17: =SUMIFS('📋 Despesas'!$J$7:$J$17825,'📋 Despesas'!$F$7:$F$17825,$B17,'📋 Despesas'!$C$7:$C$17825,J$3,'📋 Despesas'!$D$7:$D$17825,J$2) -> 0 | K17: =SUMIFS('📋 Despesas'!$J$7:$J$17825,'📋 Despesas'!$F$7:$F$17825,$B17,'📋 Despesas'!$C$7:$C$17825,K$3,'📋 Despesas'!$D$7:$D$17825,K$2) -> 0 | ... O17: =SUMIFS('📋 Despesas'!$J$7:$J$17825,'📋 Despesas'!$F$7:$F$17825,$B17,'📋 Despesas'!$C$7:$C$17825,O$3,'📋 Despesas'!$D$7:$D$17825,O$2) -> 0
C18: =SUM(D18:O18) -> 0 | D18: =SUMIFS('📋 Despesas'!$J$7:$J$17825,'📋 Despesas'!$F$7:$F$17825,$B18,'📋 Despesas'!$C$7:$C$17825,D$3,'📋 Despesas'!$D$7:$D$17825,D$2) -> 0 | E18: =SUMIFS('📋 Despesas'!$J$7:$J$17825,'📋 Despesas'!$F$7:$F$17825,$B18,'📋 Despesas'!$C$7:$C$17825,E$3,'📋 Despesas'!$D$7:$D$17825,E$2) -> 0 | F18: =SUMIFS('📋 Despesas'!$J$7:$J$17825,'📋 Despesas'!$F$7:$F$17825,$B18,'📋 Despesas'!$C$7:$C$17825,F$3,'📋 Despesas'!$D$7:$D$17825,F$2) -> 0 | G18: =SUMIFS('📋 Despesas'!$J$7:$J$17825,'📋 Despesas'!$F$7:$F$17825,$B18,'📋 Despesas'!$C$7:$C$17825,G$3,'📋 Despesas'!$D$7:$D$17825,G$2) -> 0 | H18: =SUMIFS('📋 Despesas'!$J$7:$J$17825,'📋 Despesas'!$F$7:$F$17825,$B18,'📋 Despesas'!$C$7:$C$17825,H$3,'📋 Despesas'!$D$7:$D$17825,H$2) -> 0 | I18: =SUMIFS('📋 Despesas'!$J$7:$J$17825,'📋 Despesas'!$F$7:$F$17825,$B18,'📋 Despesas'!$C$7:$C$17825,I$3,'📋 Despesas'!$D$7:$D$17825,I$2) -> 0 | J18: =SUMIFS('📋 Despesas'!$J$7:$J$17825,'📋 Despesas'!$F$7:$F$17825,$B18,'📋 Despesas'!$C$7:$C$17825,J$3,'📋 Despesas'!$D$7:$D$17825,J$2) -> 0 | K18: =SUMIFS('📋 Despesas'!$J$7:$J$17825,'📋 Despesas'!$F$7:$F$17825,$B18,'📋 Despesas'!$C$7:$C$17825,K$3,'📋 Despesas'!$D$7:$D$17825,K$2) -> 0 | ... O18: =SUMIFS('📋 Despesas'!$J$7:$J$17825,'📋 Despesas'!$F$7:$F$17825,$B18,'📋 Despesas'!$C$7:$C$17825,O$3,'📋 Despesas'!$D$7:$D$17825,O$2) -> 0
C19: =SUM(D19:O19) -> 0 | D19: =SUMIFS('📋 Despesas'!$J$7:$J$17825,'📋 Despesas'!$F$7:$F$17825,$B19,'📋 Despesas'!$C$7:$C$17825,D$3,'📋 Despesas'!$D$7:$D$17825,D$2) -> 0 | E19: =SUMIFS('📋 Despesas'!$J$7:$J$17825,'📋 Despesas'!$F$7:$F$17825,$B19,'📋 Despesas'!$C$7:$C$17825,E$3,'📋 Despesas'!$D$7:$D$17825,E$2) -> 0 | F19: =SUMIFS('📋 Despesas'!$J$7:$J$17825,'📋 Despesas'!$F$7:$F$17825,$B19,'📋 Despesas'!$C$7:$C$17825,F$3,'📋 Despesas'!$D$7:$D$17825,F$2) -> 0 | G19: =SUMIFS('📋 Despesas'!$J$7:$J$17825,'📋 Despesas'!$F$7:$F$17825,$B19,'📋 Despesas'!$C$7:$C$17825,G$3,'📋 Despesas'!$D$7:$D$17825,G$2) -> 0 | H19: =SUMIFS('📋 Despesas'!$J$7:$J$17825,'📋 Despesas'!$F$7:$F$17825,$B19,'📋 Despesas'!$C$7:$C$17825,H$3,'📋 Despesas'!$D$7:$D$17825,H$2) -> 0 | I19: =SUMIFS('📋 Despesas'!$J$7:$J$17825,'📋 Despesas'!$F$7:$F$17825,$B19,'📋 Despesas'!$C$7:$C$17825,I$3,'📋 Despesas'!$D$7:$D$17825,I$2) -> 0 | J19: =SUMIFS('📋 Despesas'!$J$7:$J$17825,'📋 Despesas'!$F$7:$F$17825,$B19,'📋 Despesas'!$C$7:$C$17825,J$3,'📋 Despesas'!$D$7:$D$17825,J$2) -> 0 | K19: =SUMIFS('📋 Despesas'!$J$7:$J$17825,'📋 Despesas'!$F$7:$F$17825,$B19,'📋 Despesas'!$C$7:$C$17825,K$3,'📋 Despesas'!$D$7:$D$17825,K$2) -> 0 | ... O19: =SUMIFS('📋 Despesas'!$J$7:$J$17825,'📋 Despesas'!$F$7:$F$17825,$B19,'📋 Despesas'!$C$7:$C$17825,O$3,'📋 Despesas'!$D$7:$D$17825,O$2) -> 0
C20: =SUM(D20:O20) -> 0 | D20: =SUMIFS('📋 Despesas'!$J$7:$J$17825,'📋 Despesas'!$F$7:$F$17825,$B20,'📋 Despesas'!$C$7:$C$17825,D$3,'📋 Despesas'!$D$7:$D$17825,D$2) -> 0 | E20: =SUMIFS('📋 Despesas'!$J$7:$J$17825,'📋 Despesas'!$F$7:$F$17825,$B20,'📋 Despesas'!$C$7:$C$17825,E$3,'📋 Despesas'!$D$7:$D$17825,E$2) -> 0 | F20: =SUMIFS('📋 Despesas'!$J$7:$J$17825,'📋 Despesas'!$F$7:$F$17825,$B20,'📋 Despesas'!$C$7:$C$17825,F$3,'📋 Despesas'!$D$7:$D$17825,F$2) -> 0 | G20: =SUMIFS('📋 Despesas'!$J$7:$J$17825,'📋 Despesas'!$F$7:$F$17825,$B20,'📋 Despesas'!$C$7:$C$17825,G$3,'📋 Despesas'!$D$7:$D$17825,G$2) -> 0 | H20: =SUMIFS('📋 Despesas'!$J$7:$J$17825,'📋 Despesas'!$F$7:$F$17825,$B20,'📋 Despesas'!$C$7:$C$17825,H$3,'📋 Despesas'!$D$7:$D$17825,H$2) -> 0 | I20: =SUMIFS('📋 Despesas'!$J$7:$J$17825,'📋 Despesas'!$F$7:$F$17825,$B20,'📋 Despesas'!$C$7:$C$17825,I$3,'📋 Despesas'!$D$7:$D$17825,I$2) -> 0 | J20: =SUMIFS('📋 Despesas'!$J$7:$J$17825,'📋 Despesas'!$F$7:$F$17825,$B20,'📋 Despesas'!$C$7:$C$17825,J$3,'📋 Despesas'!$D$7:$D$17825,J$2) -> 0 | K20: =SUMIFS('📋 Despesas'!$J$7:$J$17825,'📋 Despesas'!$F$7:$F$17825,$B20,'📋 Despesas'!$C$7:$C$17825,K$3,'📋 Despesas'!$D$7:$D$17825,K$2) -> 0 | ... O20: =SUMIFS('📋 Despesas'!$J$7:$J$17825,'📋 Despesas'!$F$7:$F$17825,$B20,'📋 Despesas'!$C$7:$C$17825,O$3,'📋 Despesas'!$D$7:$D$17825,O$2) -> 0
C21: =SUM(D21:O21) -> 0 | D21: =SUMIFS('📋 Despesas'!$J$7:$J$17825,'📋 Despesas'!$F$7:$F$17825,$B21,'📋 Despesas'!$C$7:$C$17825,D$3,'📋 Despesas'!$D$7:$D$17825,D$2) -> 0 | E21: =SUMIFS('📋 Despesas'!$J$7:$J$17825,'📋 Despesas'!$F$7:$F$17825,$B21,'📋 Despesas'!$C$7:$C$17825,E$3,'📋 Despesas'!$D$7:$D$17825,E$2) -> 0 | F21: =SUMIFS('📋 Despesas'!$J$7:$J$17825,'📋 Despesas'!$F$7:$F$17825,$B21,'📋 Despesas'!$C$7:$C$17825,F$3,'📋 Despesas'!$D$7:$D$17825,F$2) -> 0 | G21: =SUMIFS('📋 Despesas'!$J$7:$J$17825,'📋 Despesas'!$F$7:$F$17825,$B21,'📋 Despesas'!$C$7:$C$17825,G$3,'📋 Despesas'!$D$7:$D$17825,G$2) -> 0 | H21: =SUMIFS('📋 Despesas'!$J$7:$J$17825,'📋 Despesas'!$F$7:$F$17825,$B21,'📋 Despesas'!$C$7:$C$17825,H$3,'📋 Despesas'!$D$7:$D$17825,H$2) -> 0 | I21: =SUMIFS('📋 Despesas'!$J$7:$J$17825,'📋 Despesas'!$F$7:$F$17825,$B21,'📋 Despesas'!$C$7:$C$17825,I$3,'📋 Despesas'!$D$7:$D$17825,I$2) -> 0 | J21: =SUMIFS('📋 Despesas'!$J$7:$J$17825,'📋 Despesas'!$F$7:$F$17825,$B21,'📋 Despesas'!$C$7:$C$17825,J$3,'📋 Despesas'!$D$7:$D$17825,J$2) -> 0 | K21: =SUMIFS('📋 Despesas'!$J$7:$J$17825,'📋 Despesas'!$F$7:$F$17825,$B21,'📋 Despesas'!$C$7:$C$17825,K$3,'📋 Despesas'!$D$7:$D$17825,K$2) -> 0 | ... O21: =SUMIFS('📋 Despesas'!$J$7:$J$17825,'📋 Despesas'!$F$7:$F$17825,$B21,'📋 Despesas'!$C$7:$C$17825,O$3,'📋 Despesas'!$D$7:$D$17825,O$2) -> 0
B22: DAS | C22: =SUM(D22:O22) -> 600 | D22: =SUMIFS('📋 Despesas'!$J$7:$J$17825,'📋 Despesas'!$F$7:$F$17825,$B22,'📋 Despesas'!$C$7:$C$17825,D$3,'📋 Despesas'!$D$7:$D$17825,D$2) -> 0 | E22: =SUMIFS('📋 Despesas'!$J$7:$J$17825,'📋 Despesas'!$F$7:$F$17825,$B22,'📋 Despesas'!$C$7:$C$17825,E$3,'📋 Despesas'!$D$7:$D$17825,E$2) -> 0 | F22: =SUMIFS('📋 Despesas'!$J$7:$J$17825,'📋 Despesas'!$F$7:$F$17825,$B22,'📋 Despesas'!$C$7:$C$17825,F$3,'📋 Despesas'!$D$7:$D$17825,F$2) -> 0 | G22: =SUMIFS('📋 Despesas'!$J$7:$J$17825,'📋 Despesas'!$F$7:$F$17825,$B22,'📋 Despesas'!$C$7:$C$17825,G$3,'📋 Despesas'!$D$7:$D$17825,G$2) -> 0 | H22: =SUMIFS('📋 Despesas'!$J$7:$J$17825,'📋 Despesas'!$F$7:$F$17825,$B22,'📋 Despesas'!$C$7:$C$17825,H$3,'📋 Despesas'!$D$7:$D$17825,H$2) -> 0 | I22: =SUMIFS('📋 Despesas'!$J$7:$J$17825,'📋 Despesas'!$F$7:$F$17825,$B22,'📋 Despesas'!$C$7:$C$17825,I$3,'📋 Despesas'!$D$7:$D$17825,I$2) -> 0 | J22: =SUMIFS('📋 Despesas'!$J$7:$J$17825,'📋 Despesas'!$F$7:$F$17825,$B22,'📋 Despesas'!$C$7:$C$17825,J$3,'📋 Despesas'!$D$7:$D$17825,J$2) -> 600 | K22: =SUMIFS('📋 Despesas'!$J$7:$J$17825,'📋 Despesas'!$F$7:$F$17825,$B22,'📋 Despesas'!$C$7:$C$17825,K$3,'📋 Despesas'!$D$7:$D$17825,K$2) -> 0 | ... O22: =SUMIFS('📋 Despesas'!$J$7:$J$17825,'📋 Despesas'!$F$7:$F$17825,$B22,'📋 Despesas'!$C$7:$C$17825,O$3,'📋 Despesas'!$D$7:$D$17825,O$2) -> 0
B23: TAXAS | C23: =SUM(D23:O23) -> 0 | D23: =SUMIFS('📋 Despesas'!$J$7:$J$17825,'📋 Despesas'!$F$7:$F$17825,$B23,'📋 Despesas'!$C$7:$C$17825,D$3,'📋 Despesas'!$D$7:$D$17825,D$2) -> 0 | E23: =SUMIFS('📋 Despesas'!$J$7:$J$17825,'📋 Despesas'!$F$7:$F$17825,$B23,'📋 Despesas'!$C$7:$C$17825,E$3,'📋 Despesas'!$D$7:$D$17825,E$2) -> 0 | F23: =SUMIFS('📋 Despesas'!$J$7:$J$17825,'📋 Despesas'!$F$7:$F$17825,$B23,'📋 Despesas'!$C$7:$C$17825,F$3,'📋 Despesas'!$D$7:$D$17825,F$2) -> 0 | G23: =SUMIFS('📋 Despesas'!$J$7:$J$17825,'📋 Despesas'!$F$7:$F$17825,$B23,'📋 Despesas'!$C$7:$C$17825,G$3,'📋 Despesas'!$D$7:$D$17825,G$2) -> 0 | H23: =SUMIFS('📋 Despesas'!$J$7:$J$17825,'📋 Despesas'!$F$7:$F$17825,$B23,'📋 Despesas'!$C$7:$C$17825,H$3,'📋 Despesas'!$D$7:$D$17825,H$2) -> 0 | I23: =SUMIFS('📋 Despesas'!$J$7:$J$17825,'📋 Despesas'!$F$7:$F$17825,$B23,'📋 Despesas'!$C$7:$C$17825,I$3,'📋 Despesas'!$D$7:$D$17825,I$2) -> 0 | J23: =SUMIFS('📋 Despesas'!$J$7:$J$17825,'📋 Despesas'!$F$7:$F$17825,$B23,'📋 Despesas'!$C$7:$C$17825,J$3,'📋 Despesas'!$D$7:$D$17825,J$2) -> 0 | K23: =SUMIFS('📋 Despesas'!$J$7:$J$17825,'📋 Despesas'!$F$7:$F$17825,$B23,'📋 Despesas'!$C$7:$C$17825,K$3,'📋 Despesas'!$D$7:$D$17825,K$2) -> 0 | ... O23: =SUMIFS('📋 Despesas'!$J$7:$J$17825,'📋 Despesas'!$F$7:$F$17825,$B23,'📋 Despesas'!$C$7:$C$17825,O$3,'📋 Despesas'!$D$7:$D$17825,O$2) -> 0
